Workbook

Sheet Matrix
B1: Not enough data
B2: Data as of July 3, 2024 | D2: Client
E3: Communication | H3: Decision | K3: Drive | N3: Emotion | Q3: Environment | T3: Preference | W3: Priority | Z3: TOTAL
B4: XP | E4: Synchronous | F4: Asynchronous | H4: Data-Driven | I4: Intuition | K4: Small tangible goals | L4: Towards visionary ideas | N4: Investment | O4: Separation | Q4: Flexibility | R4: Structure | T4: One goal in mind | U4: With detailed instructions | W4: Speed of execution | X4: Accuracy of decisions
B5: Communication | C5: Synchronous | D5: # | E5: {=COUNTIFS( rawv3!$F:$F, "<>Ongoing", INDIRECT("rawv3!" & ADDRESS(1, MATCH($D$2 & " " & E$3, rawv3!$1:$1, 0), 4) & ":" & ADDRESS(1048576, MATCH($D$2 & " " & E$3, rawv3!$1:$1, 0), 4)), E$4, INDIRECT("rawv3!" & ADDRESS(1, MATCH($B$4 & " " & $B5, rawv3!$1:$1, 0), 4) & ":" & ADDRESS(1048576, MATCH($B$4 & " " & $B5, rawv3!$1:$1, 0), 4)), $C5 )} -> 595 | F5: {=COUNTIFS( rawv3!$F:$F, "<>Ongoing", INDIRECT("rawv3!" & ADDRESS(1, MATCH($D$2 & " " & E$3, rawv3!$1:$1, 0), 4) & ":" & ADDRESS(1048576, MATCH($D$2 & " " & E$3, rawv3!$1:$1, 0), 4)), F$4, INDIRECT("rawv3!" & ADDRESS(1, MATCH($B$4 & " " & $B5, rawv3!$1:$1, 0), 4) & ":" & ADDRESS(1048576, MATCH($B$4 & " " & $B5, rawv3!$1:$1, 0), 4)), $C5 )} -> 379 | H5: {=COUNTIFS( rawv3!$F:$F, "<>Ongoing", INDIRECT("rawv3!" & ADDRESS(1, MATCH($D$2 & " " & H$3, rawv3!$1:$1, 0), 4) & ":" & ADDRESS(1048576, MATCH($D$2 & " " & H$3, rawv3!$1:$1, 0), 4)), H$4, INDIRECT("rawv3!" & ADDRESS(1, MATCH($B$4 & " " & $B5, rawv3!$1:$1, 0), 4) & ":" & ADDRESS(1048576, MATCH($B$4 & " " & $B5, rawv3!$1:$1, 0), 4)), $C5 )} -> 591 | I5: {=COUNTIFS( rawv3!$F:$F, "<>Ongoing", INDIRECT("rawv3!" & ADDRESS(1, MATCH($D$2 & " " & H$3, rawv3!$1:$1, 0), 4) & ":" & ADDRESS(1048576, MATCH($D$2 & " " & H$3, rawv3!$1:$1, 0), 4)), I$4, INDIRECT("rawv3!" & ADDRESS(1, MATCH($B$4 & " " & $B5, rawv3!$1:$1, 0), 4) & ":" & ADDRESS(1048576, MATCH($B$4 & " " & $B5, rawv3!$1:$1, 0), 4)), $C5 )} -> 385 | K5: {=COUNTIFS( rawv3!$F:$F, "<>Ongoing", INDIRECT("rawv3!" & ADDRESS(1, MATCH($D$2 & " " & K$3, rawv3!$1:$1, 0), 4) & ":" & ADDRESS(1048576, MATCH($D$2 & " " & K$3, rawv3!$1:$1, 0), 4)), K$4, INDIRECT("rawv3!" & ADDRESS(1, MATCH($B$4 & " " & $B5, rawv3!$1:$1, 0), 4) & ":" & ADDRESS(1048576, MATCH($B$4 & " " & $B5, rawv3!$1:$1, 0), 4)), $C5 )} -> 445 | L5: {=COUNTIFS( rawv3!$F:$F, "<>Ongoing", INDIRECT("rawv3!" & ADDRESS(1, MATCH($D$2 & " " & K$3, rawv3!$1:$1, 0), 4) & ":" & ADDRESS(1048576, MATCH($D$2 & " " & K$3, rawv3!$1:$1, 0), 4)), L$4, INDIRECT("rawv3!" & ADDRESS(1, MATCH($B$4 & " " & $B5, rawv3!$1:$1, 0), 4) & ":" & ADDRESS(1048576, MATCH($B$4 & " " & $B5, rawv3!$1:$1, 0), 4)), $C5 )} -> 530 | N5: {=COUNTIFS( rawv3!$F:$F, "<>Ongoing", INDIRECT("rawv3!" & ADDRESS(1, MATCH($D$2 & " " & N$3, rawv3!$1:$1, 0), 4) & ":" & ADDRESS(1048576, MATCH($D$2 & " " & N$3, rawv3!$1:$1, 0), 4)), N$4, INDIRECT("rawv3!" & ADDRESS(1, MATCH($B$4 & " " & $B5, rawv3!$1:$1, 0), 4) & ":" & ADDRESS(1048576, MATCH($B$4 & " " & $B5, rawv3!$1:$1, 0), 4)), $C5 )} -> 595 | O5: {=COUNTIFS( rawv3!$F:$F, "<>Ongoing", INDIRECT("rawv3!" & ADDRESS(1, MATCH($D$2 & " " & N$3, rawv3!$1:$1, 0), 4) & ":" & ADDRESS(1048576, MATCH($D$2 & " " & N$3, rawv3!$1:$1, 0), 4)), O$4, INDIRECT("rawv3!" & ADDRESS(1, MATCH($B$4 & " " & $B5, rawv3!$1:$1, 0), 4) & ":" & ADDRESS(1048576, MATCH($B$4 & " " & $B5, rawv3!$1:$1, 0), 4)), $C5 )} -> 381 | Q5: {=COUNTIFS( rawv3!$F:$F, "<>Ongoing", INDIRECT("rawv3!" & ADDRESS(1, MATCH($D$2 & " " & Q$3, rawv3!$1:$1, 0), 4) & ":" & ADDRESS(1048576, MATCH($D$2 & " " & Q$3, rawv3!$1:$1, 0), 4)), Q$4, INDIRECT("rawv3!" & ADDRESS(1, MATCH($B$4 & " " & $B5, rawv3!$1:$1, 0), 4) & ":" & ADDRESS(1048576, MATCH($B$4 & " " & $B5, rawv3!$1:$1, 0), 4)), $C5 )} -> 690 | R5: {=COUNTIFS( rawv3!$F:$F, "<>Ongoing", INDIRECT("rawv3!" & ADDRESS(1, MATCH($D$2 & " " & Q$3, rawv3!$1:$1, 0), 4) & ":" & ADDRESS(1048576, MATCH($D$2 & " " & Q$3, rawv3!$1:$1, 0), 4)), R$4, INDIRECT("rawv3!" & ADDRESS(1, MATCH($B$4 & " " & $B5, rawv3!$1:$1, 0), 4) & ":" & ADDRESS(1048576, MATCH($B$4 & " " & $B5, rawv3!$1:$1, 0), 4)), $C5 )} -> 285 | T5: {=COUNTIFS( rawv3!$F:$F, "<>Ongoing", INDIRECT("rawv3!" & ADDRESS(1, MATCH($D$2 & " " & T$3, rawv3!$1:$1, 0), 4) & ":" & ADDRESS(1048576, MATCH($D$2 & " " & T$3, rawv3!$1:$1, 0), 4)), T$4, INDIRECT("rawv3!" & ADDRESS(1, MATCH($B$4 & " " & $B5, rawv3!$1:$1, 0), 4) & ":" & ADDRESS(1048576, MATCH($B$4 & " " & $B5, rawv3!$1:$1, 0), 4)), $C5 )} -> 743 | U5: {=COUNTIFS( rawv3!$F:$F, "<>Ongoing", INDIRECT("rawv3!" & ADDRESS(1, MATCH($D$2 & " " & T$3, rawv3!$1:$1, 0), 4) & ":" & ADDRESS(1048576, MATCH($D$2 & " " & T$3, rawv3!$1:$1, 0), 4)), U$4, INDIRECT("rawv3!" & ADDRESS(1, MATCH($B$4 & " " & $B5, rawv3!$1:$1, 0), 4) & ":" & ADDRESS(1048576, MATCH($B$4 & " " & $B5, rawv3!$1:$1, 0), 4)), $C5 )} -> 232 | W5: {=COUNTIFS( rawv3!$F:$F, "<>Ongoing", INDIRECT("rawv3!" & ADDRESS(1, MATCH($D$2 & " " & W$3, rawv3!$1:$1, 0), 4) & ":" & ADDRESS(1048576, MATCH($D$2 & " " & W$3, rawv3!$1:$1, 0), 4)), W$4, INDIRECT("rawv3!" & ADDRESS(1, MATCH($B$4 & " " & $B5, rawv3!$1:$1, 0), 4) & ":" & ADDRESS(1048576, MATCH($B$4 & " " & $B5, rawv3!$1:$1, 0), 4)), $C5 )} -> 436 | X5: {=COUNTIFS( rawv3!$F:$F, "<>Ongoing", INDIRECT("rawv3!" & ADDRESS(1, MATCH($D$2 & " " & W$3, rawv3!$1:$1, 0), 4) & ":" & ADDRESS(1048576, MATCH($D$2 & " " & W$3, rawv3!$1:$1, 0), 4)), X$4, INDIRECT("rawv3!" & ADDRESS(1, MATCH($B$4 & " " & $B5, rawv3!$1:$1, 0), 4) & ":" & ADDRESS(1048576, MATCH($B$4 & " " & $B5, rawv3!$1:$1, 0), 4)), $C5 )} -> 540 | Z5: {=COUNTIFS( rawv3!$F:$F, "<>Ongoing", INDIRECT("rawv3!" & ADDRESS(1, MATCH($B$4 & " " & $B5, rawv3!$1:$1, 0), 4) & ":" & ADDRESS(1048576, MATCH($B$4 & " " & $B5, rawv3!$1:$1, 0), 4)), $C5)} -> 976
D6: F90D % | E6: {=COUNTIFS( rawv3!$F:$F, "Success", INDIRECT("rawv3!" & ADDRESS(1, MATCH($D$2 & " " & E$3, rawv3!$1:$1, 0), 4) & ":" & ADDRESS(1048576, MATCH($D$2 & " " & E$3, rawv3!$1:$1, 0), 4)), E$4, INDIRECT("rawv3!" & ADDRESS(1, MATCH($B$4 & " " & $B5, rawv3!$1:$1, 0), 4) & ":" & ADDRESS(1048576, MATCH($B$4 & " " & $B5, rawv3!$1:$1, 0), 4)), $C5 )/E5} -> 0.77142857 | F6: {=COUNTIFS( rawv3!$F:$F, "Success", INDIRECT("rawv3!" & ADDRESS(1, MATCH($D$2 & " " & E$3, rawv3!$1:$1, 0), 4) & ":" & ADDRESS(1048576, MATCH($D$2 & " " & E$3, rawv3!$1:$1, 0), 4)), F$4, INDIRECT("rawv3!" & ADDRESS(1, MATCH($B$4 & " " & $B5, rawv3!$1:$1, 0), 4) & ":" & ADDRESS(1048576, MATCH($B$4 & " " & $B5, rawv3!$1:$1, 0), 4)), $C5 )/F5} -> 0.77308707 | H6: {=COUNTIFS( rawv3!$F:$F, "Success", INDIRECT("rawv3!" & ADDRESS(1, MATCH($D$2 & " " & H$3, rawv3!$1:$1, 0), 4) & ":" & ADDRESS(1048576, MATCH($D$2 & " " & H$3, rawv3!$1:$1, 0), 4)), H$4, INDIRECT("rawv3!" & ADDRESS(1, MATCH($B$4 & " " & $B5, rawv3!$1:$1, 0), 4) & ":" & ADDRESS(1048576, MATCH($B$4 & " " & $B5, rawv3!$1:$1, 0), 4)), $C5 )/H5} -> 0.77834179 | I6: {=COUNTIFS( rawv3!$F:$F, "Success", INDIRECT("rawv3!" & ADDRESS(1, MATCH($D$2 & " " & H$3, rawv3!$1:$1, 0), 4) & ":" & ADDRESS(1048576, MATCH($D$2 & " " & H$3, rawv3!$1:$1, 0), 4)), I$4, INDIRECT("rawv3!" & ADDRESS(1, MATCH($B$4 & " " & $B5, rawv3!$1:$1, 0), 4) & ":" & ADDRESS(1048576, MATCH($B$4 & " " & $B5, rawv3!$1:$1, 0), 4)), $C5 )/I5} -> 0.76363636 | K6: {=COUNTIFS( rawv3!$F:$F, "Success", INDIRECT("rawv3!" & ADDRESS(1, MATCH($D$2 & " " & K$3, rawv3!$1:$1, 0), 4) & ":" & ADDRESS(1048576, MATCH($D$2 & " " & K$3, rawv3!$1:$1, 0), 4)), K$4, INDIRECT("rawv3!" & ADDRESS(1, MATCH($B$4 & " " & $B5, rawv3!$1:$1, 0), 4) & ":" & ADDRESS(1048576, MATCH($B$4 & " " & $B5, rawv3!$1:$1, 0), 4)), $C5 )/K5} -> 0.74157303 | L6: {=COUNTIFS( rawv3!$F:$F, "Success", INDIRECT("rawv3!" & ADDRESS(1, MATCH($D$2 & " " & K$3, rawv3!$1:$1, 0), 4) & ":" & ADDRESS(1048576, MATCH($D$2 & " " & K$3, rawv3!$1:$1, 0), 4)), L$4, INDIRECT("rawv3!" & ADDRESS(1, MATCH($B$4 & " " & $B5, rawv3!$1:$1, 0), 4) & ":" & ADDRESS(1048576, MATCH($B$4 & " " & $B5, rawv3!$1:$1, 0), 4)), $C5 )/L5} -> 0.8 | N6: {=COUNTIFS( rawv3!$F:$F, "Success", INDIRECT("rawv3!" & ADDRESS(1, MATCH($D$2 & " " & N$3, rawv3!$1:$1, 0), 4) & ":" & ADDRESS(1048576, MATCH($D$2 & " " & N$3, rawv3!$1:$1, 0), 4)), N$4, INDIRECT("rawv3!" & ADDRESS(1, MATCH($B$4 & " " & $B5, rawv3!$1:$1, 0), 4) & ":" & ADDRESS(1048576, MATCH($B$4 & " " & $B5, rawv3!$1:$1, 0), 4)), $C5 )/N5} -> 0.77310924 | O6: {=COUNTIFS( rawv3!$F:$F, "Success", INDIRECT("rawv3!" & ADDRESS(1, MATCH($D$2 & " " & N$3, rawv3!$1:$1, 0), 4) & ":" & ADDRESS(1048576, MATCH($D$2 & " " & N$3, rawv3!$1:$1, 0), 4)), O$4, INDIRECT("rawv3!" & ADDRESS(1, MATCH($B$4 & " " & $B5, rawv3!$1:$1, 0), 4) & ":" & ADDRESS(1048576, MATCH($B$4 & " " & $B5, rawv3!$1:$1, 0), 4)), $C5 )/O5} -> 0.77165354 | Q6: {=COUNTIFS( rawv3!$F:$F, "Success", INDIRECT("rawv3!" & ADDRESS(1, MATCH($D$2 & " " & Q$3, rawv3!$1:$1, 0), 4) & ":" & ADDRESS(1048576, MATCH($D$2 & " " & Q$3, rawv3!$1:$1, 0), 4)), Q$4, INDIRECT("rawv3!" & ADDRESS(1, MATCH($B$4 & " " & $B5, rawv3!$1:$1, 0), 4) & ":" & ADDRESS(1048576, MATCH($B$4 & " " & $B5, rawv3!$1:$1, 0), 4)), $C5 )/Q5} -> 0.77681159 | R6: {=COUNTIFS( rawv3!$F:$F, "Success", INDIRECT("rawv3!" & ADDRESS(1, MATCH($D$2 & " " & Q$3, rawv3!$1:$1, 0), 4) & ":" & ADDRESS(1048576, MATCH($D$2 & " " & Q$3, rawv3!$1:$1, 0), 4)), R$4, INDIRECT("rawv3!" & ADDRESS(1, MATCH($B$4 & " " & $B5, rawv3!$1:$1, 0), 4) & ":" & ADDRESS(1048576, MATCH($B$4 & " " & $B5, rawv3!$1:$1, 0), 4)), $C5 )/R5} -> 0.76491228 | T6: {=COUNTIFS( rawv3!$F:$F, "Success", INDIRECT("rawv3!" & ADDRESS(1, MATCH($D$2 & " " & T$3, rawv3!$1:$1, 0), 4) & ":" & ADDRESS(1048576, MATCH($D$2 & " " & T$3, rawv3!$1:$1, 0), 4)), T$4, INDIRECT("rawv3!" & ADDRESS(1, MATCH($B$4 & " " & $B5, rawv3!$1:$1, 0), 4) & ":" & ADDRESS(1048576, MATCH($B$4 & " " & $B5, rawv3!$1:$1, 0), 4)), $C5 )/T5} -> 0.7846568 | U6: {=COUNTIFS( rawv3!$F:$F, "Success", INDIRECT("rawv3!" & ADDRESS(1, MATCH($D$2 & " " & T$3, rawv3!$1:$1, 0), 4) & ":" & ADDRESS(1048576, MATCH($D$2 & " " & T$3, rawv3!$1:$1, 0), 4)), U$4, INDIRECT("rawv3!" & ADDRESS(1, MATCH($B$4 & " " & $B5, rawv3!$1:$1, 0), 4) & ":" & ADDRESS(1048576, MATCH($B$4 & " " & $B5, rawv3!$1:$1, 0), 4)), $C5 )/U5} -> 0.73275862 | W6: {=COUNTIFS( rawv3!$F:$F, "Success", INDIRECT("rawv3!" & ADDRESS(1, MATCH($D$2 & " " & W$3, rawv3!$1:$1, 0), 4) & ":" & ADDRESS(1048576, MATCH($D$2 & " " & W$3, rawv3!$1:$1, 0), 4)), W$4, INDIRECT("rawv3!" & ADDRESS(1, MATCH($B$4 & " " & $B5, rawv3!$1:$1, 0), 4) & ":" & ADDRESS(1048576, MATCH($B$4 & " " & $B5, rawv3!$1:$1, 0), 4)), $C5 )/W5} -> 0.76146789 | X6: {=COUNTIFS( rawv3!$F:$F, "Success", INDIRECT("rawv3!" & ADDRESS(1, MATCH($D$2 & " " & W$3, rawv3!$1:$1, 0), 4) & ":" & ADDRESS(1048576, MATCH($D$2 & " " & W$3, rawv3!$1:$1, 0), 4)), X$4, INDIRECT("rawv3!" & ADDRESS(1, MATCH($B$4 & " " & $B5, rawv3!$1:$1, 0), 4) & ":" & ADDRESS(1048576, MATCH($B$4 & " " & $B5, rawv3!$1:$1, 0), 4)), $C5 )/X5} -> 0.78148148 | Z6: {=COUNTIFS( rawv3!$F:$F, "Success", INDIRECT("rawv3!" & ADDRESS(1, MATCH($B$4 & " " & $B5, rawv3!$1:$1, 0), 4) & ":" & ADDRESS(1048576, MATCH($B$4 & " " & $B5, rawv3!$1:$1, 0), 4)), $C5)/Z5} -> 0.77254098 | AA6: {=COUNTIFS( rawv3!$F:$F, "Success", INDIRECT("rawv3!" & ADDRESS(1, MATCH($B$4 & " " & $B5, rawv3!$1:$1, 0), 4) & ":" & ADDRESS(1048576, MATCH($B$4 & " " & $B5, rawv3!$1:$1, 0), 4)), $C5)} -> 754
C7: Asynchronous | D7: # | E7: {=COUNTIFS( rawv3!$F:$F, "<>Ongoing", INDIRECT("rawv3!" & ADDRESS(1, MATCH($D$2 & " " & E$3, rawv3!$1:$1, 0), 4) & ":" & ADDRESS(1048576, MATCH($D$2 & " " & E$3, rawv3!$1:$1, 0), 4)), E$4, INDIRECT("rawv3!" & ADDRESS(1, MATCH($B$4 & " " & $B5, rawv3!$1:$1, 0), 4) & ":" & ADDRESS(1048576, MATCH($B$4 & " " & $B5, rawv3!$1:$1, 0), 4)), $C7 )} -> 688 | F7: {=COUNTIFS( rawv3!$F:$F, "<>Ongoing", INDIRECT("rawv3!" & ADDRESS(1, MATCH($D$2 & " " & E$3, rawv3!$1:$1, 0), 4) & ":" & ADDRESS(1048576, MATCH($D$2 & " " & E$3, rawv3!$1:$1, 0), 4)), F$4, INDIRECT("rawv3!" & ADDRESS(1, MATCH($B$4 & " " & $B5, rawv3!$1:$1, 0), 4) & ":" & ADDRESS(1048576, MATCH($B$4 & " " & $B5, rawv3!$1:$1, 0), 4)), $C7 )} -> 871 | H7: {=COUNTIFS( rawv3!$F:$F, "<>Ongoing", INDIRECT("rawv3!" & ADDRESS(1, MATCH($D$2 & " " & H$3, rawv3!$1:$1, 0), 4) & ":" & ADDRESS(1048576, MATCH($D$2 & " " & H$3, rawv3!$1:$1, 0), 4)), H$4, INDIRECT("rawv3!" & ADDRESS(1, MATCH($B$4 & " " & $B5, rawv3!$1:$1, 0), 4) & ":" & ADDRESS(1048576, MATCH($B$4 & " " & $B5, rawv3!$1:$1, 0), 4)), $C7 )} -> 953 | I7: {=COUNTIFS( rawv3!$F:$F, "<>Ongoing", INDIRECT("rawv3!" & ADDRESS(1, MATCH($D$2 & " " & H$3, rawv3!$1:$1, 0), 4) & ":" & ADDRESS(1048576, MATCH($D$2 & " " & H$3, rawv3!$1:$1, 0), 4)), I$4, INDIRECT("rawv3!" & ADDRESS(1, MATCH($B$4 & " " & $B5, rawv3!$1:$1, 0), 4) & ":" & ADDRESS(1048576, MATCH($B$4 & " " & $B5, rawv3!$1:$1, 0), 4)), $C7 )} -> 609 | K7: {=COUNTIFS( rawv3!$F:$F, "<>Ongoing", INDIRECT("rawv3!" & ADDRESS(1, MATCH($D$2 & " " & K$3, rawv3!$1:$1, 0), 4) & ":" & ADDRESS(1048576, MATCH($D$2 & " " & K$3, rawv3!$1:$1, 0), 4)), K$4, INDIRECT("rawv3!" & ADDRESS(1, MATCH($B$4 & " " & $B5, rawv3!$1:$1, 0), 4) & ":" & ADDRESS(1048576, MATCH($B$4 & " " & $B5, rawv3!$1:$1, 0), 4)), $C7 )} -> 777 | L7: {=COUNTIFS( rawv3!$F:$F, "<>Ongoing", INDIRECT("rawv3!" & ADDRESS(1, MATCH($D$2 & " " & K$3, rawv3!$1:$1, 0), 4) & ":" & ADDRESS(1048576, MATCH($D$2 & " " & K$3, rawv3!$1:$1, 0), 4)), L$4, INDIRECT("rawv3!" & ADDRESS(1, MATCH($B$4 & " " & $B5, rawv3!$1:$1, 0), 4) & ":" & ADDRESS(1048576, MATCH($B$4 & " " & $B5, rawv3!$1:$1, 0), 4)), $C7 )} -> 785 | N7: {=COUNTIFS( rawv3!$F:$F, "<>Ongoing", INDIRECT("rawv3!" & ADDRESS(1, MATCH($D$2 & " " & N$3, rawv3!$1:$1, 0), 4) & ":" & ADDRESS(1048576, MATCH($D$2 & " " & N$3, rawv3!$1:$1, 0), 4)), N$4, INDIRECT("rawv3!" & ADDRESS(1, MATCH($B$4 & " " & $B5, rawv3!$1:$1, 0), 4) & ":" & ADDRESS(1048576, MATCH($B$4 & " " & $B5, rawv3!$1:$1, 0), 4)), $C7 )} -> 926 | O7: {=COUNTIFS( rawv3!$F:$F, "<>Ongoing", INDIRECT("rawv3!" & ADDRESS(1, MATCH($D$2 & " " & N$3, rawv3!$1:$1, 0), 4) & ":" & ADDRESS(1048576, MATCH($D$2 & " " & N$3, rawv3!$1:$1, 0), 4)), O$4, INDIRECT("rawv3!" & ADDRESS(1, MATCH($B$4 & " " & $B5, rawv3!$1:$1, 0), 4) & ":" & ADDRESS(1048576, MATCH($B$4 & " " & $B5, rawv3!$1:$1, 0), 4)), $C7 )} -> 636 | Q7: {=COUNTIFS( rawv3!$F:$F, "<>Ongoing", INDIRECT("rawv3!" & ADDRESS(1, MATCH($D$2 & " " & Q$3, rawv3!$1:$1, 0), 4) & ":" & ADDRESS(1048576, MATCH($D$2 & " " & Q$3, rawv3!$1:$1, 0), 4)), Q$4, INDIRECT("rawv3!" & ADDRESS(1, MATCH($B$4 & " " & $B5, rawv3!$1:$1, 0), 4) & ":" & ADDRESS(1048576, MATCH($B$4 & " " & $B5, rawv3!$1:$1, 0), 4)), $C7 )} -> 1150 | R7: {=COUNTIFS( rawv3!$F:$F, "<>Ongoing", INDIRECT("rawv3!" & ADDRESS(1, MATCH($D$2 & " " & Q$3, rawv3!$1:$1, 0), 4) & ":" & ADDRESS(1048576, MATCH($D$2 & " " & Q$3, rawv3!$1:$1, 0), 4)), R$4, INDIRECT("rawv3!" & ADDRESS(1, MATCH($B$4 & " " & $B5, rawv3!$1:$1, 0), 4) & ":" & ADDRESS(1048576, MATCH($B$4 & " " & $B5, rawv3!$1:$1, 0), 4)), $C7 )} -> 411 | T7: {=COUNTIFS( rawv3!$F:$F, "<>Ongoing", INDIRECT("rawv3!" & ADDRESS(1, MATCH($D$2 & " " & T$3, rawv3!$1:$1, 0), 4) & ":" & ADDRESS(1048576, MATCH($D$2 & " " & T$3, rawv3!$1:$1, 0), 4)), T$4, INDIRECT("rawv3!" & ADDRESS(1, MATCH($B$4 & " " & $B5, rawv3!$1:$1, 0), 4) & ":" & ADDRESS(1048576, MATCH($B$4 & " " & $B5, rawv3!$1:$1, 0), 4)), $C7 )} -> 1178 | U7: {=COUNTIFS( rawv3!$F:$F, "<>Ongoing", INDIRECT("rawv3!" & ADDRESS(1, MATCH($D$2 & " " & T$3, rawv3!$1:$1, 0), 4) & ":" & ADDRESS(1048576, MATCH($D$2 & " " & T$3, rawv3!$1:$1, 0), 4)), U$4, INDIRECT("rawv3!" & ADDRESS(1, MATCH($B$4 & " " & $B5, rawv3!$1:$1, 0), 4) & ":" & ADDRESS(1048576, MATCH($B$4 & " " & $B5, rawv3!$1:$1, 0), 4)), $C7 )} -> 384 | W7: {=COUNTIFS( rawv3!$F:$F, "<>Ongoing", INDIRECT("rawv3!" & ADDRESS(1, MATCH($D$2 & " " & W$3, rawv3!$1:$1, 0), 4) & ":" & ADDRESS(1048576, MATCH($D$2 & " " & W$3, rawv3!$1:$1, 0), 4)), W$4, INDIRECT("rawv3!" & ADDRESS(1, MATCH($B$4 & " " & $B5, rawv3!$1:$1, 0), 4) & ":" & ADDRESS(1048576, MATCH($B$4 & " " & $B5, rawv3!$1:$1, 0), 4)), $C7 )} -> 691 | X7: {=COUNTIFS( rawv3!$F:$F, "<>Ongoing", INDIRECT("rawv3!" & ADDRESS(1, MATCH($D$2 & " " & W$3, rawv3!$1:$1, 0), 4) & ":" & ADDRESS(1048576, MATCH($D$2 & " " & W$3, rawv3!$1:$1, 0), 4)), X$4, INDIRECT("rawv3!" & ADDRESS(1, MATCH($B$4 & " " & $B5, rawv3!$1:$1, 0), 4) & ":" & ADDRESS(1048576, MATCH($B$4 & " " & $B5, rawv3!$1:$1, 0), 4)), $C7 )} -> 871 | Z7: {=COUNTIFS( rawv3!$F:$F, "<>Ongoing", INDIRECT("rawv3!" & ADDRESS(1, MATCH($B$4 & " " & $B5, rawv3!$1:$1, 0), 4) & ":" & ADDRESS(1048576, MATCH($B$4 & " " & $B5, rawv3!$1:$1, 0), 4)), $C7)} -> 1562
D8: F90D % | E8: {=COUNTIFS( rawv3!$F:$F, "Success", INDIRECT("rawv3!" & ADDRESS(1, MATCH($D$2 & " " & E$3, rawv3!$1:$1, 0), 4) & ":" & ADDRESS(1048576, MATCH($D$2 & " " & E$3, rawv3!$1:$1, 0), 4)), E$4, INDIRECT("rawv3!" & ADDRESS(1, MATCH($B$4 & " " & $B5, rawv3!$1:$1, 0), 4) & ":" & ADDRESS(1048576, MATCH($B$4 & " " & $B5, rawv3!$1:$1, 0), 4)), $C7 )/E7} -> 0.78633721 | F8: {=COUNTIFS( rawv3!$F:$F, "Success", INDIRECT("rawv3!" & ADDRESS(1, MATCH($D$2 & " " & E$3, rawv3!$1:$1, 0), 4) & ":" & ADDRESS(1048576, MATCH($D$2 & " " & E$3, rawv3!$1:$1, 0), 4)), F$4, INDIRECT("rawv3!" & ADDRESS(1, MATCH($B$4 & " " & $B5, rawv3!$1:$1, 0), 4) & ":" & ADDRESS(1048576, MATCH($B$4 & " " & $B5, rawv3!$1:$1, 0), 4)), $C7 )/F7} -> 0.80941447 | H8: {=COUNTIFS( rawv3!$F:$F, "Success", INDIRECT("rawv3!" & ADDRESS(1, MATCH($D$2 & " " & H$3, rawv3!$1:$1, 0), 4) & ":" & ADDRESS(1048576, MATCH($D$2 & " " & H$3, rawv3!$1:$1, 0), 4)), H$4, INDIRECT("rawv3!" & ADDRESS(1, MATCH($B$4 & " " & $B5, rawv3!$1:$1, 0), 4) & ":" & ADDRESS(1048576, MATCH($B$4 & " " & $B5, rawv3!$1:$1, 0), 4)), $C7 )/H7} -> 0.8069255 | I8: {=COUNTIFS( rawv3!$F:$F, "Success", INDIRECT("rawv3!" & ADDRESS(1, MATCH($D$2 & " " & H$3, rawv3!$1:$1, 0), 4) & ":" & ADDRESS(1048576, MATCH($D$2 & " " & H$3, rawv3!$1:$1, 0), 4)), I$4, INDIRECT("rawv3!" & ADDRESS(1, MATCH($B$4 & " " & $B5, rawv3!$1:$1, 0), 4) & ":" & ADDRESS(1048576, MATCH($B$4 & " " & $B5, rawv3!$1:$1, 0), 4)), $C7 )/I7} -> 0.78817734 | K8: {=COUNTIFS( rawv3!$F:$F, "Success", INDIRECT("rawv3!" & ADDRESS(1, MATCH($D$2 & " " & K$3, rawv3!$1:$1, 0), 4) & ":" & ADDRESS(1048576, MATCH($D$2 & " " & K$3, rawv3!$1:$1, 0), 4)), K$4, INDIRECT("rawv3!" & ADDRESS(1, MATCH($B$4 & " " & $B5, rawv3!$1:$1, 0), 4) & ":" & ADDRESS(1048576, MATCH($B$4 & " " & $B5, rawv3!$1:$1, 0), 4)), $C7 )/K7} -> 0.81338481 | L8: {=COUNTIFS( rawv3!$F:$F, "Success", INDIRECT("rawv3!" & ADDRESS(1, MATCH($D$2 & " " & K$3, rawv3!$1:$1, 0), 4) & ":" & ADDRESS(1048576, MATCH($D$2 & " " & K$3, rawv3!$1:$1, 0), 4)), L$4, INDIRECT("rawv3!" & ADDRESS(1, MATCH($B$4 & " " & $B5, rawv3!$1:$1, 0), 4) & ":" & ADDRESS(1048576, MATCH($B$4 & " " & $B5, rawv3!$1:$1, 0), 4)), $C7 )/L7} -> 0.78598726 | N8: {=COUNTIFS( rawv3!$F:$F, "Success", INDIRECT("rawv3!" & ADDRESS(1, MATCH($D$2 & " " & N$3, rawv3!$1:$1, 0), 4) & ":" & ADDRESS(1048576, MATCH($D$2 & " " & N$3, rawv3!$1:$1, 0), 4)), N$4, INDIRECT("rawv3!" & ADDRESS(1, MATCH($B$4 & " " & $B5, rawv3!$1:$1, 0), 4) & ":" & ADDRESS(1048576, MATCH($B$4 & " " & $B5, rawv3!$1:$1, 0), 4)), $C7 )/N7} -> 0.80669546 | O8: {=COUNTIFS( rawv3!$F:$F, "Success", INDIRECT("rawv3!" & ADDRESS(1, MATCH($D$2 & " " & N$3, rawv3!$1:$1, 0), 4) & ":" & ADDRESS(1048576, MATCH($D$2 & " " & N$3, rawv3!$1:$1, 0), 4)), O$4, INDIRECT("rawv3!" & ADDRESS(1, MATCH($B$4 & " " & $B5, rawv3!$1:$1, 0), 4) & ":" & ADDRESS(1048576, MATCH($B$4 & " " & $B5, rawv3!$1:$1, 0), 4)), $C7 )/O7} -> 0.78930818 | Q8: {=COUNTIFS( rawv3!$F:$F, "Success", INDIRECT("rawv3!" & ADDRESS(1, MATCH($D$2 & " " & Q$3, rawv3!$1:$1, 0), 4) & ":" & ADDRESS(1048576, MATCH($D$2 & " " & Q$3, rawv3!$1:$1, 0), 4)), Q$4, INDIRECT("rawv3!" & ADDRESS(1, MATCH($B$4 & " " & $B5, rawv3!$1:$1, 0), 4) & ":" & ADDRESS(1048576, MATCH($B$4 & " " & $B5, rawv3!$1:$1, 0), 4)), $C7 )/Q7} -> 0.80608696 | R8: {=COUNTIFS( rawv3!$F:$F, "Success", INDIRECT("rawv3!" & ADDRESS(1, MATCH($D$2 & " " & Q$3, rawv3!$1:$1, 0), 4) & ":" & ADDRESS(1048576, MATCH($D$2 & " " & Q$3, rawv3!$1:$1, 0), 4)), R$4, INDIRECT("rawv3!" & ADDRESS(1, MATCH($B$4 & " " & $B5, rawv3!$1:$1, 0), 4) & ":" & ADDRESS(1048576, MATCH($B$4 & " " & $B5, rawv3!$1:$1, 0), 4)), $C7 )/R7} -> 0.7810219 | T8: {=COUNTIFS( rawv3!$F:$F, "Success", INDIRECT("rawv3!" & ADDRESS(1, MATCH($D$2 & " " & T$3, rawv3!$1:$1, 0), 4) & ":" & ADDRESS(1048576, MATCH($D$2 & " " & T$3, rawv3!$1:$1, 0), 4)), T$4, INDIRECT("rawv3!" & ADDRESS(1, MATCH($B$4 & " " & $B5, rawv3!$1:$1, 0), 4) & ":" & ADDRESS(1048576, MATCH($B$4 & " " & $B5, rawv3!$1:$1, 0), 4)), $C7 )/T7} -> 0.79541596 | U8: {=COUNTIFS( rawv3!$F:$F, "Success", INDIRECT("rawv3!" & ADDRESS(1, MATCH($D$2 & " " & T$3, rawv3!$1:$1, 0), 4) & ":" & ADDRESS(1048576, MATCH($D$2 & " " & T$3, rawv3!$1:$1, 0), 4)), U$4, INDIRECT("rawv3!" & ADDRESS(1, MATCH($B$4 & " " & $B5, rawv3!$1:$1, 0), 4) & ":" & ADDRESS(1048576, MATCH($B$4 & " " & $B5, rawv3!$1:$1, 0), 4)), $C7 )/U7} -> 0.8125 | W8: {=COUNTIFS( rawv3!$F:$F, "Success", INDIRECT("rawv3!" & ADDRESS(1, MATCH($D$2 & " " & W$3, rawv3!$1:$1, 0), 4) & ":" & ADDRESS(1048576, MATCH($D$2 & " " & W$3, rawv3!$1:$1, 0), 4)), W$4, INDIRECT("rawv3!" & ADDRESS(1, MATCH($B$4 & " " & $B5, rawv3!$1:$1, 0), 4) & ":" & ADDRESS(1048576, MATCH($B$4 & " " & $B5, rawv3!$1:$1, 0), 4)), $C7 )/W7} -> 0.79015919 | X8: {=COUNTIFS( rawv3!$F:$F, "Success", INDIRECT("rawv3!" & ADDRESS(1, MATCH($D$2 & " " & W$3, rawv3!$1:$1, 0), 4) & ":" & ADDRESS(1048576, MATCH($D$2 & " " & W$3, rawv3!$1:$1, 0), 4)), X$4, INDIRECT("rawv3!" & ADDRESS(1, MATCH($B$4 & " " & $B5, rawv3!$1:$1, 0), 4) & ":" & ADDRESS(1048576, MATCH($B$4 & " " & $B5, rawv3!$1:$1, 0), 4)), $C7 )/X7} -> 0.80711825 | Z8: {=COUNTIFS( rawv3!$F:$F, "Success", INDIRECT("rawv3!" & ADDRESS(1, MATCH($B$4 & " " & $B5, rawv3!$1:$1, 0), 4) & ":" & ADDRESS(1048576, MATCH($B$4 & " " & $B5, rawv3!$1:$1, 0), 4)), $C7)/Z7} -> 0.79961588 | AA8: {=COUNTIFS( rawv3!$F:$F, "Success", INDIRECT("rawv3!" & ADDRESS(1, MATCH($B$4 & " " & $B5, rawv3!$1:$1, 0), 4) & ":" & ADDRESS(1048576, MATCH($B$4 & " " & $B5, rawv3!$1:$1, 0), 4)), $C7)} -> 1249
B10: Decision | C10: Data-Driven | D10: # | E10: {=COUNTIFS( rawv3!$F:$F, "<>Ongoing", INDIRECT("rawv3!" & ADDRESS(1, MATCH($D$2 & " " & E$3, rawv3!$1:$1, 0), 4) & ":" & ADDRESS(1048576, MATCH($D$2 & " " & E$3, rawv3!$1:$1, 0), 4)), E$4, INDIRECT("rawv3!" & ADDRESS(1, MATCH($B$4 & " " & $B10, rawv3!$1:$1, 0), 4) & ":" & ADDRESS(1048576, MATCH($B$4 & " " & $B10, rawv3!$1:$1, 0), 4)), $C10 )} -> 1196 | F10: {=COUNTIFS( rawv3!$F:$F, "<>Ongoing", INDIRECT("rawv3!" & ADDRESS(1, MATCH($D$2 & " " & E$3, rawv3!$1:$1, 0), 4) & ":" & ADDRESS(1048576, MATCH($D$2 & " " & E$3, rawv3!$1:$1, 0), 4)), F$4, INDIRECT("rawv3!" & ADDRESS(1, MATCH($B$4 & " " & $B10, rawv3!$1:$1, 0), 4) & ":" & ADDRESS(1048576, MATCH($B$4 & " " & $B10, rawv3!$1:$1, 0), 4)), $C10 )} -> 1163 | H10: {=COUNTIFS( rawv3!$F:$F, "<>Ongoing", INDIRECT("rawv3!" & ADDRESS(1, MATCH($D$2 & " " & H$3, rawv3!$1:$1, 0), 4) & ":" & ADDRESS(1048576, MATCH($D$2 & " " & H$3, rawv3!$1:$1, 0), 4)), H$4, INDIRECT("rawv3!" & ADDRESS(1, MATCH($B$4 & " " & $B10, rawv3!$1:$1, 0), 4) & ":" & ADDRESS(1048576, MATCH($B$4 & " " & $B10, rawv3!$1:$1, 0), 4)), $C10 )} -> 1460 | I10: {=COUNTIFS( rawv3!$F:$F, "<>Ongoing", INDIRECT("rawv3!" & ADDRESS(1, MATCH($D$2 & " " & H$3, rawv3!$1:$1, 0), 4) & ":" & ADDRESS(1048576, MATCH($D$2 & " " & H$3, rawv3!$1:$1, 0), 4)), I$4, INDIRECT("rawv3!" & ADDRESS(1, MATCH($B$4 & " " & $B10, rawv3!$1:$1, 0), 4) & ":" & ADDRESS(1048576, MATCH($B$4 & " " & $B10, rawv3!$1:$1, 0), 4)), $C10 )} -> 904 | K10: {=COUNTIFS( rawv3!$F:$F, "<>Ongoing", INDIRECT("rawv3!" & ADDRESS(1, MATCH($D$2 & " " & K$3, rawv3!$1:$1, 0), 4) & ":" & ADDRESS(1048576, MATCH($D$2 & " " & K$3, rawv3!$1:$1, 0), 4)), K$4, INDIRECT("rawv3!" & ADDRESS(1, MATCH($B$4 & " " & $B10, rawv3!$1:$1, 0), 4) & ":" & ADDRESS(1048576, MATCH($B$4 & " " & $B10, rawv3!$1:$1, 0), 4)), $C10 )} -> 1145 | L10: {=COUNTIFS( rawv3!$F:$F, "<>Ongoing", INDIRECT("rawv3!" & ADDRESS(1, MATCH($D$2 & " " & K$3, rawv3!$1:$1, 0), 4) & ":" & ADDRESS(1048576, MATCH($D$2 & " " & K$3, rawv3!$1:$1, 0), 4)), L$4, INDIRECT("rawv3!" & ADDRESS(1, MATCH($B$4 & " " & $B10, rawv3!$1:$1, 0), 4) & ":" & ADDRESS(1048576, MATCH($B$4 & " " & $B10, rawv3!$1:$1, 0), 4)), $C10 )} -> 1218 | N10: {=COUNTIFS( rawv3!$F:$F, "<>Ongoing", INDIRECT("rawv3!" & ADDRESS(1, MATCH($D$2 & " " & N$3, rawv3!$1:$1, 0), 4) & ":" & ADDRESS(1048576, MATCH($D$2 & " " & N$3, rawv3!$1:$1, 0), 4)), N$4, INDIRECT("rawv3!" & ADDRESS(1, MATCH($B$4 & " " & $B10, rawv3!$1:$1, 0), 4) & ":" & ADDRESS(1048576, MATCH($B$4 & " " & $B10, rawv3!$1:$1, 0), 4)), $C10 )} -> 1408 | O10: {=COUNTIFS( rawv3!$F:$F, "<>Ongoing", INDIRECT("rawv3!" & ADDRESS(1, MATCH($D$2 & " " & N$3, rawv3!$1:$1, 0), 4) & ":" & ADDRESS(1048576, MATCH($D$2 & " " & N$3, rawv3!$1:$1, 0), 4)), O$4, INDIRECT("rawv3!" & ADDRESS(1, MATCH($B$4 & " " & $B10, rawv3!$1:$1, 0), 4) & ":" & ADDRESS(1048576, MATCH($B$4 & " " & $B10, rawv3!$1:$1, 0), 4)), $C10 )} -> 956 | Q10: {=COUNTIFS( rawv3!$F:$F, "<>Ongoing", INDIRECT("rawv3!" & ADDRESS(1, MATCH($D$2 & " " & Q$3, rawv3!$1:$1, 0), 4) & ":" & ADDRESS(1048576, MATCH($D$2 & " " & Q$3, rawv3!$1:$1, 0), 4)), Q$4, INDIRECT("rawv3!" & ADDRESS(1, MATCH($B$4 & " " & $B10, rawv3!$1:$1, 0), 4) & ":" & ADDRESS(1048576, MATCH($B$4 & " " & $B10, rawv3!$1:$1, 0), 4)), $C10 )} -> 1719 | R10: {=COUNTIFS( rawv3!$F:$F, "<>Ongoing", INDIRECT("rawv3!" & ADDRESS(1, MATCH($D$2 & " " & Q$3, rawv3!$1:$1, 0), 4) & ":" & ADDRESS(1048576, MATCH($D$2 & " " & Q$3, rawv3!$1:$1, 0), 4)), R$4, INDIRECT("rawv3!" & ADDRESS(1, MATCH($B$4 & " " & $B10, rawv3!$1:$1, 0), 4) & ":" & ADDRESS(1048576, MATCH($B$4 & " " & $B10, rawv3!$1:$1, 0), 4)), $C10 )} -> 643 | T10: {=COUNTIFS( rawv3!$F:$F, "<>Ongoing", INDIRECT("rawv3!" & ADDRESS(1, MATCH($D$2 & " " & T$3, rawv3!$1:$1, 0), 4) & ":" & ADDRESS(1048576, MATCH($D$2 & " " & T$3, rawv3!$1:$1, 0), 4)), T$4, INDIRECT("rawv3!" & ADDRESS(1, MATCH($B$4 & " " & $B10, rawv3!$1:$1, 0), 4) & ":" & ADDRESS(1048576, MATCH($B$4 & " " & $B10, rawv3!$1:$1, 0), 4)), $C10 )} -> 1793 | U10: {=COUNTIFS( rawv3!$F:$F, "<>Ongoing", INDIRECT("rawv3!" & ADDRESS(1, MATCH($D$2 & " " & T$3, rawv3!$1:$1, 0), 4) & ":" & ADDRESS(1048576, MATCH($D$2 & " " & T$3, rawv3!$1:$1, 0), 4)), U$4, INDIRECT("rawv3!" & ADDRESS(1, MATCH($B$4 & " " & $B10, rawv3!$1:$1, 0), 4) & ":" & ADDRESS(1048576, MATCH($B$4 & " " & $B10, rawv3!$1:$1, 0), 4)), $C10 )} -> 570 | W10: {=COUNTIFS( rawv3!$F:$F, "<>Ongoing", INDIRECT("rawv3!" & ADDRESS(1, MATCH($D$2 & " " & W$3, rawv3!$1:$1, 0), 4) & ":" & ADDRESS(1048576, MATCH($D$2 & " " & W$3, rawv3!$1:$1, 0), 4)), W$4, INDIRECT("rawv3!" & ADDRESS(1, MATCH($B$4 & " " & $B10, rawv3!$1:$1, 0), 4) & ":" & ADDRESS(1048576, MATCH($B$4 & " " & $B10, rawv3!$1:$1, 0), 4)), $C10 )} -> 1045 | X10: {=COUNTIFS( rawv3!$F:$F, "<>Ongoing", INDIRECT("rawv3!" & ADDRESS(1, MATCH($D$2 & " " & W$3, rawv3!$1:$1, 0), 4) & ":" & ADDRESS(1048576, MATCH($D$2 & " " & W$3, rawv3!$1:$1, 0), 4)), X$4, INDIRECT("rawv3!" & ADDRESS(1, MATCH($B$4 & " " & $B10, rawv3!$1:$1, 0), 4) & ":" & ADDRESS(1048576, MATCH($B$4 & " " & $B10, rawv3!$1:$1, 0), 4)), $C10 )} -> 1319 | Z10: {=COUNTIFS( rawv3!$F:$F, "<>Ongoing", INDIRECT("rawv3!" & ADDRESS(1, MATCH($B$4 & " " & $B10, rawv3!$1:$1, 0), 4) & ":" & ADDRESS(1048576, MATCH($B$4 & " " & $B10, rawv3!$1:$1, 0), 4)), $C10)} -> 2364
D11: F90D % | E11: {=COUNTIFS( rawv3!$F:$F, "Success", INDIRECT("rawv3!" & ADDRESS(1, MATCH($D$2 & " " & E$3, rawv3!$1:$1, 0), 4) & ":" & ADDRESS(1048576, MATCH($D$2 & " " & E$3, rawv3!$1:$1, 0), 4)), E$4, INDIRECT("rawv3!" & ADDRESS(1, MATCH($B$4 & " " & $B10, rawv3!$1:$1, 0), 4) & ":" & ADDRESS(1048576, MATCH($B$4 & " " & $B10, rawv3!$1:$1, 0), 4)), $C10 )/E10} -> 0.77675585 | F11: {=COUNTIFS( rawv3!$F:$F, "Success", INDIRECT("rawv3!" & ADDRESS(1, MATCH($D$2 & " " & E$3, rawv3!$1:$1, 0), 4) & ":" & ADDRESS(1048576, MATCH($D$2 & " " & E$3, rawv3!$1:$1, 0), 4)), F$4, INDIRECT("rawv3!" & ADDRESS(1, MATCH($B$4 & " " & $B10, rawv3!$1:$1, 0), 4) & ":" & ADDRESS(1048576, MATCH($B$4 & " " & $B10, rawv3!$1:$1, 0), 4)), $C10 )/F10} -> 0.8022356 | H11: {=COUNTIFS( rawv3!$F:$F, "Success", INDIRECT("rawv3!" & ADDRESS(1, MATCH($D$2 & " " & H$3, rawv3!$1:$1, 0), 4) & ":" & ADDRESS(1048576, MATCH($D$2 & " " & H$3, rawv3!$1:$1, 0), 4)), H$4, INDIRECT("rawv3!" & ADDRESS(1, MATCH($B$4 & " " & $B10, rawv3!$1:$1, 0), 4) & ":" & ADDRESS(1048576, MATCH($B$4 & " " & $B10, rawv3!$1:$1, 0), 4)), $C10 )/H10} -> 0.79657534 | I11: {=COUNTIFS( rawv3!$F:$F, "Success", INDIRECT("rawv3!" & ADDRESS(1, MATCH($D$2 & " " & H$3, rawv3!$1:$1, 0), 4) & ":" & ADDRESS(1048576, MATCH($D$2 & " " & H$3, rawv3!$1:$1, 0), 4)), I$4, INDIRECT("rawv3!" & ADDRESS(1, MATCH($B$4 & " " & $B10, rawv3!$1:$1, 0), 4) & ":" & ADDRESS(1048576, MATCH($B$4 & " " & $B10, rawv3!$1:$1, 0), 4)), $C10 )/I10} -> 0.77876106 | K11: {=COUNTIFS( rawv3!$F:$F, "Success", INDIRECT("rawv3!" & ADDRESS(1, MATCH($D$2 & " " & K$3, rawv3!$1:$1, 0), 4) & ":" & ADDRESS(1048576, MATCH($D$2 & " " & K$3, rawv3!$1:$1, 0), 4)), K$4, INDIRECT("rawv3!" & ADDRESS(1, MATCH($B$4 & " " & $B10, rawv3!$1:$1, 0), 4) & ":" & ADDRESS(1048576, MATCH($B$4 & " " & $B10, rawv3!$1:$1, 0), 4)), $C10 )/K10} -> 0.78689956 | L11: {=COUNTIFS( rawv3!$F:$F, "Success", INDIRECT("rawv3!" & ADDRESS(1, MATCH($D$2 & " " & K$3, rawv3!$1:$1, 0), 4) & ":" & ADDRESS(1048576, MATCH($D$2 & " " & K$3, rawv3!$1:$1, 0), 4)), L$4, INDIRECT("rawv3!" & ADDRESS(1, MATCH($B$4 & " " & $B10, rawv3!$1:$1, 0), 4) & ":" & ADDRESS(1048576, MATCH($B$4 & " " & $B10, rawv3!$1:$1, 0), 4)), $C10 )/L10} -> 0.79310345 | N11: {=COUNTIFS( rawv3!$F:$F, "Success", INDIRECT("rawv3!" & ADDRESS(1, MATCH($D$2 & " " & N$3, rawv3!$1:$1, 0), 4) & ":" & ADDRESS(1048576, MATCH($D$2 & " " & N$3, rawv3!$1:$1, 0), 4)), N$4, INDIRECT("rawv3!" & ADDRESS(1, MATCH($B$4 & " " & $B10, rawv3!$1:$1, 0), 4) & ":" & ADDRESS(1048576, MATCH($B$4 & " " & $B10, rawv3!$1:$1, 0), 4)), $C10 )/N10} -> 0.79332386 | O11: {=COUNTIFS( rawv3!$F:$F, "Success", INDIRECT("rawv3!" & ADDRESS(1, MATCH($D$2 & " " & N$3, rawv3!$1:$1, 0), 4) & ":" & ADDRESS(1048576, MATCH($D$2 & " " & N$3, rawv3!$1:$1, 0), 4)), O$4, INDIRECT("rawv3!" & ADDRESS(1, MATCH($B$4 & " " & $B10, rawv3!$1:$1, 0), 4) & ":" & ADDRESS(1048576, MATCH($B$4 & " " & $B10, rawv3!$1:$1, 0), 4)), $C10 )/O10} -> 0.78451883 | Q11: {=COUNTIFS( rawv3!$F:$F, "Success", INDIRECT("rawv3!" & ADDRESS(1, MATCH($D$2 & " " & Q$3, rawv3!$1:$1, 0), 4) & ":" & ADDRESS(1048576, MATCH($D$2 & " " & Q$3, rawv3!$1:$1, 0), 4)), Q$4, INDIRECT("rawv3!" & ADDRESS(1, MATCH($B$4 & " " & $B10, rawv3!$1:$1, 0), 4) & ":" & ADDRESS(1048576, MATCH($B$4 & " " & $B10, rawv3!$1:$1, 0), 4)), $C10 )/Q10} -> 0.79348458 | R11: {=COUNTIFS( rawv3!$F:$F, "Success", INDIRECT("rawv3!" & ADDRESS(1, MATCH($D$2 & " " & Q$3, rawv3!$1:$1, 0), 4) & ":" & ADDRESS(1048576, MATCH($D$2 & " " & Q$3, rawv3!$1:$1, 0), 4)), R$4, INDIRECT("rawv3!" & ADDRESS(1, MATCH($B$4 & " " & $B10, rawv3!$1:$1, 0), 4) & ":" & ADDRESS(1048576, MATCH($B$4 & " " & $B10, rawv3!$1:$1, 0), 4)), $C10 )/R10} -> 0.7807154 | T11: {=COUNTIFS( rawv3!$F:$F, "Success", INDIRECT("rawv3!" & ADDRESS(1, MATCH($D$2 & " " & T$3, rawv3!$1:$1, 0), 4) & ":" & ADDRESS(1048576, MATCH($D$2 & " " & T$3, rawv3!$1:$1, 0), 4)), T$4, INDIRECT("rawv3!" & ADDRESS(1, MATCH($B$4 & " " & $B10, rawv3!$1:$1, 0), 4) & ":" & ADDRESS(1048576, MATCH($B$4 & " " & $B10, rawv3!$1:$1, 0), 4)), $C10 )/T10} -> 0.79085332 | U11: {=COUNTIFS( rawv3!$F:$F, "Success", INDIRECT("rawv3!" & ADDRESS(1, MATCH($D$2 & " " & T$3, rawv3!$1:$1, 0), 4) & ":" & ADDRESS(1048576, MATCH($D$2 & " " & T$3, rawv3!$1:$1, 0), 4)), U$4, INDIRECT("rawv3!" & ADDRESS(1, MATCH($B$4 & " " & $B10, rawv3!$1:$1, 0), 4) & ":" & ADDRESS(1048576, MATCH($B$4 & " " & $B10, rawv3!$1:$1, 0), 4)), $C10 )/U10} -> 0.78596491 | W11: {=COUNTIFS( rawv3!$F:$F, "Success", INDIRECT("rawv3!" & ADDRESS(1, MATCH($D$2 & " " & W$3, rawv3!$1:$1, 0), 4) & ":" & ADDRESS(1048576, MATCH($D$2 & " " & W$3, rawv3!$1:$1, 0), 4)), W$4, INDIRECT("rawv3!" & ADDRESS(1, MATCH($B$4 & " " & $B10, rawv3!$1:$1, 0), 4) & ":" & ADDRESS(1048576, MATCH($B$4 & " " & $B10, rawv3!$1:$1, 0), 4)), $C10 )/W10} -> 0.77990431 | X11: {=COUNTIFS( rawv3!$F:$F, "Success", INDIRECT("rawv3!" & ADDRESS(1, MATCH($D$2 & " " & W$3, rawv3!$1:$1, 0), 4) & ":" & ADDRESS(1048576, MATCH($D$2 & " " & W$3, rawv3!$1:$1, 0), 4)), X$4, INDIRECT("rawv3!" & ADDRESS(1, MATCH($B$4 & " " & $B10, rawv3!$1:$1, 0), 4) & ":" & ADDRESS(1048576, MATCH($B$4 & " " & $B10, rawv3!$1:$1, 0), 4)), $C10 )/X10} -> 0.79757392 | Z11: {=COUNTIFS( rawv3!$F:$F, "Success", INDIRECT("rawv3!" & ADDRESS(1, MATCH($B$4 & " " & $B10, rawv3!$1:$1, 0), 4) & ":" & ADDRESS(1048576, MATCH($B$4 & " " & $B10, rawv3!$1:$1, 0), 4)), $C10)/Z10} -> 0.78976311 | AA11: {=COUNTIFS( rawv3!$F:$F, "Success", INDIRECT("rawv3!" & ADDRESS(1, MATCH($B$4 & " " & $B10, rawv3!$1:$1, 0), 4) & ":" & ADDRESS(1048576, MATCH($B$4 & " " & $B10, rawv3!$1:$1, 0), 4)), $C10)} -> 1867
C12: Intuition | D12: # | E12: {=COUNTIFS( rawv3!$F:$F, "<>Ongoing", INDIRECT("rawv3!" & ADDRESS(1, MATCH($D$2 & " " & E$3, rawv3!$1:$1, 0), 4) & ":" & ADDRESS(1048576, MATCH($D$2 & " " & E$3, rawv3!$1:$1, 0), 4)), E$4, INDIRECT("rawv3!" & ADDRESS(1, MATCH($B$4 & " " & $B10, rawv3!$1:$1, 0), 4) & ":" & ADDRESS(1048576, MATCH($B$4 & " " & $B10, rawv3!$1:$1, 0), 4)), $C12 )} -> 87 | F12: {=COUNTIFS( rawv3!$F:$F, "<>Ongoing", INDIRECT("rawv3!" & ADDRESS(1, MATCH($D$2 & " " & E$3, rawv3!$1:$1, 0), 4) & ":" & ADDRESS(1048576, MATCH($D$2 & " " & E$3, rawv3!$1:$1, 0), 4)), F$4, INDIRECT("rawv3!" & ADDRESS(1, MATCH($B$4 & " " & $B10, rawv3!$1:$1, 0), 4) & ":" & ADDRESS(1048576, MATCH($B$4 & " " & $B10, rawv3!$1:$1, 0), 4)), $C12 )} -> 87 | H12: {=COUNTIFS( rawv3!$F:$F, "<>Ongoing", INDIRECT("rawv3!" & ADDRESS(1, MATCH($D$2 & " " & H$3, rawv3!$1:$1, 0), 4) & ":" & ADDRESS(1048576, MATCH($D$2 & " " & H$3, rawv3!$1:$1, 0), 4)), H$4, INDIRECT("rawv3!" & ADDRESS(1, MATCH($B$4 & " " & $B10, rawv3!$1:$1, 0), 4) & ":" & ADDRESS(1048576, MATCH($B$4 & " " & $B10, rawv3!$1:$1, 0), 4)), $C12 )} -> 84 | I12: {=COUNTIFS( rawv3!$F:$F, "<>Ongoing", INDIRECT("rawv3!" & ADDRESS(1, MATCH($D$2 & " " & H$3, rawv3!$1:$1, 0), 4) & ":" & ADDRESS(1048576, MATCH($D$2 & " " & H$3, rawv3!$1:$1, 0), 4)), I$4, INDIRECT("rawv3!" & ADDRESS(1, MATCH($B$4 & " " & $B10, rawv3!$1:$1, 0), 4) & ":" & ADDRESS(1048576, MATCH($B$4 & " " & $B10, rawv3!$1:$1, 0), 4)), $C12 )} -> 90 | K12: {=COUNTIFS( rawv3!$F:$F, "<>Ongoing", INDIRECT("rawv3!" & ADDRESS(1, MATCH($D$2 & " " & K$3, rawv3!$1:$1, 0), 4) & ":" & ADDRESS(1048576, MATCH($D$2 & " " & K$3, rawv3!$1:$1, 0), 4)), K$4, INDIRECT("rawv3!" & ADDRESS(1, MATCH($B$4 & " " & $B10, rawv3!$1:$1, 0), 4) & ":" & ADDRESS(1048576, MATCH($B$4 & " " & $B10, rawv3!$1:$1, 0), 4)), $C12 )} -> 77 | L12: {=COUNTIFS( rawv3!$F:$F, "<>Ongoing", INDIRECT("rawv3!" & ADDRESS(1, MATCH($D$2 & " " & K$3, rawv3!$1:$1, 0), 4) & ":" & ADDRESS(1048576, MATCH($D$2 & " " & K$3, rawv3!$1:$1, 0), 4)), L$4, INDIRECT("rawv3!" & ADDRESS(1, MATCH($B$4 & " " & $B10, rawv3!$1:$1, 0), 4) & ":" & ADDRESS(1048576, MATCH($B$4 & " " & $B10, rawv3!$1:$1, 0), 4)), $C12 )} -> 97 | N12: {=COUNTIFS( rawv3!$F:$F, "<>Ongoing", INDIRECT("rawv3!" & ADDRESS(1, MATCH($D$2 & " " & N$3, rawv3!$1:$1, 0), 4) & ":" & ADDRESS(1048576, MATCH($D$2 & " " & N$3, rawv3!$1:$1, 0), 4)), N$4, INDIRECT("rawv3!" & ADDRESS(1, MATCH($B$4 & " " & $B10, rawv3!$1:$1, 0), 4) & ":" & ADDRESS(1048576, MATCH($B$4 & " " & $B10, rawv3!$1:$1, 0), 4)), $C12 )} -> 113 | O12: {=COUNTIFS( rawv3!$F:$F, "<>Ongoing", INDIRECT("rawv3!" & ADDRESS(1, MATCH($D$2 & " " & N$3, rawv3!$1:$1, 0), 4) & ":" & ADDRESS(1048576, MATCH($D$2 & " " & N$3, rawv3!$1:$1, 0), 4)), O$4, INDIRECT("rawv3!" & ADDRESS(1, MATCH($B$4 & " " & $B10, rawv3!$1:$1, 0), 4) & ":" & ADDRESS(1048576, MATCH($B$4 & " " & $B10, rawv3!$1:$1, 0), 4)), $C12 )} -> 61 | Q12: {=COUNTIFS( rawv3!$F:$F, "<>Ongoing", INDIRECT("rawv3!" & ADDRESS(1, MATCH($D$2 & " " & Q$3, rawv3!$1:$1, 0), 4) & ":" & ADDRESS(1048576, MATCH($D$2 & " " & Q$3, rawv3!$1:$1, 0), 4)), Q$4, INDIRECT("rawv3!" & ADDRESS(1, MATCH($B$4 & " " & $B10, rawv3!$1:$1, 0), 4) & ":" & ADDRESS(1048576, MATCH($B$4 & " " & $B10, rawv3!$1:$1, 0), 4)), $C12 )} -> 121 | R12: {=COUNTIFS( rawv3!$F:$F, "<>Ongoing", INDIRECT("rawv3!" & ADDRESS(1, MATCH($D$2 & " " & Q$3, rawv3!$1:$1, 0), 4) & ":" & ADDRESS(1048576, MATCH($D$2 & " " & Q$3, rawv3!$1:$1, 0), 4)), R$4, INDIRECT("rawv3!" & ADDRESS(1, MATCH($B$4 & " " & $B10, rawv3!$1:$1, 0), 4) & ":" & ADDRESS(1048576, MATCH($B$4 & " " & $B10, rawv3!$1:$1, 0), 4)), $C12 )} -> 53 | T12: {=COUNTIFS( rawv3!$F:$F, "<>Ongoing", INDIRECT("rawv3!" & ADDRESS(1, MATCH($D$2 & " " & T$3, rawv3!$1:$1, 0), 4) & ":" & ADDRESS(1048576, MATCH($D$2 & " " & T$3, rawv3!$1:$1, 0), 4)), T$4, INDIRECT("rawv3!" & ADDRESS(1, MATCH($B$4 & " " & $B10, rawv3!$1:$1, 0), 4) & ":" & ADDRESS(1048576, MATCH($B$4 & " " & $B10, rawv3!$1:$1, 0), 4)), $C12 )} -> 128 | U12: {=COUNTIFS( rawv3!$F:$F, "<>Ongoing", INDIRECT("rawv3!" & ADDRESS(1, MATCH($D$2 & " " & T$3, rawv3!$1:$1, 0), 4) & ":" & ADDRESS(1048576, MATCH($D$2 & " " & T$3, rawv3!$1:$1, 0), 4)), U$4, INDIRECT("rawv3!" & ADDRESS(1, MATCH($B$4 & " " & $B10, rawv3!$1:$1, 0), 4) & ":" & ADDRESS(1048576, MATCH($B$4 & " " & $B10, rawv3!$1:$1, 0), 4)), $C12 )} -> 46 | W12: {=COUNTIFS( rawv3!$F:$F, "<>Ongoing", INDIRECT("rawv3!" & ADDRESS(1, MATCH($D$2 & " " & W$3, rawv3!$1:$1, 0), 4) & ":" & ADDRESS(1048576, MATCH($D$2 & " " & W$3, rawv3!$1:$1, 0), 4)), W$4, INDIRECT("rawv3!" & ADDRESS(1, MATCH($B$4 & " " & $B10, rawv3!$1:$1, 0), 4) & ":" & ADDRESS(1048576, MATCH($B$4 & " " & $B10, rawv3!$1:$1, 0), 4)), $C12 )} -> 82 | X12: {=COUNTIFS( rawv3!$F:$F, "<>Ongoing", INDIRECT("rawv3!" & ADDRESS(1, MATCH($D$2 & " " & W$3, rawv3!$1:$1, 0), 4) & ":" & ADDRESS(1048576, MATCH($D$2 & " " & W$3, rawv3!$1:$1, 0), 4)), X$4, INDIRECT("rawv3!" & ADDRESS(1, MATCH($B$4 & " " & $B10, rawv3!$1:$1, 0), 4) & ":" & ADDRESS(1048576, MATCH($B$4 & " " & $B10, rawv3!$1:$1, 0), 4)), $C12 )} -> 92 | Z12: {=COUNTIFS( rawv3!$F:$F, "<>Ongoing", INDIRECT("rawv3!" & ADDRESS(1, MATCH($B$4 & " " & $B10, rawv3!$1:$1, 0), 4) & ":" & ADDRESS(1048576, MATCH($B$4 & " " & $B10, rawv3!$1:$1, 0), 4)), $C12)} -> 174
D13: F90D % | E13: {=COUNTIFS( rawv3!$F:$F, "Success", INDIRECT("rawv3!" & ADDRESS(1, MATCH($D$2 & " " & E$3, rawv3!$1:$1, 0), 4) & ":" & ADDRESS(1048576, MATCH($D$2 & " " & E$3, rawv3!$1:$1, 0), 4)), E$4, INDIRECT("rawv3!" & ADDRESS(1, MATCH($B$4 & " " & $B10, rawv3!$1:$1, 0), 4) & ":" & ADDRESS(1048576, MATCH($B$4 & " " & $B10, rawv3!$1:$1, 0), 4)), $C12 )/E12} -> 0.81609195 | F13: {=COUNTIFS( rawv3!$F:$F, "Success", INDIRECT("rawv3!" & ADDRESS(1, MATCH($D$2 & " " & E$3, rawv3!$1:$1, 0), 4) & ":" & ADDRESS(1048576, MATCH($D$2 & " " & E$3, rawv3!$1:$1, 0), 4)), F$4, INDIRECT("rawv3!" & ADDRESS(1, MATCH($B$4 & " " & $B10, rawv3!$1:$1, 0), 4) & ":" & ADDRESS(1048576, MATCH($B$4 & " " & $B10, rawv3!$1:$1, 0), 4)), $C12 )/F12} -> 0.74712644 | H13: {=COUNTIFS( rawv3!$F:$F, "Success", INDIRECT("rawv3!" & ADDRESS(1, MATCH($D$2 & " " & H$3, rawv3!$1:$1, 0), 4) & ":" & ADDRESS(1048576, MATCH($D$2 & " " & H$3, rawv3!$1:$1, 0), 4)), H$4, INDIRECT("rawv3!" & ADDRESS(1, MATCH($B$4 & " " & $B10, rawv3!$1:$1, 0), 4) & ":" & ADDRESS(1048576, MATCH($B$4 & " " & $B10, rawv3!$1:$1, 0), 4)), $C12 )/H12} -> 0.78571429 | I13: {=COUNTIFS( rawv3!$F:$F, "Success", INDIRECT("rawv3!" & ADDRESS(1, MATCH($D$2 & " " & H$3, rawv3!$1:$1, 0), 4) & ":" & ADDRESS(1048576, MATCH($D$2 & " " & H$3, rawv3!$1:$1, 0), 4)), I$4, INDIRECT("rawv3!" & ADDRESS(1, MATCH($B$4 & " " & $B10, rawv3!$1:$1, 0), 4) & ":" & ADDRESS(1048576, MATCH($B$4 & " " & $B10, rawv3!$1:$1, 0), 4)), $C12 )/I12} -> 0.77777778 | K13: {=COUNTIFS( rawv3!$F:$F, "Success", INDIRECT("rawv3!" & ADDRESS(1, MATCH($D$2 & " " & K$3, rawv3!$1:$1, 0), 4) & ":" & ADDRESS(1048576, MATCH($D$2 & " " & K$3, rawv3!$1:$1, 0), 4)), K$4, INDIRECT("rawv3!" & ADDRESS(1, MATCH($B$4 & " " & $B10, rawv3!$1:$1, 0), 4) & ":" & ADDRESS(1048576, MATCH($B$4 & " " & $B10, rawv3!$1:$1, 0), 4)), $C12 )/K12} -> 0.79220779 | L13: {=COUNTIFS( rawv3!$F:$F, "Success", INDIRECT("rawv3!" & ADDRESS(1, MATCH($D$2 & " " & K$3, rawv3!$1:$1, 0), 4) & ":" & ADDRESS(1048576, MATCH($D$2 & " " & K$3, rawv3!$1:$1, 0), 4)), L$4, INDIRECT("rawv3!" & ADDRESS(1, MATCH($B$4 & " " & $B10, rawv3!$1:$1, 0), 4) & ":" & ADDRESS(1048576, MATCH($B$4 & " " & $B10, rawv3!$1:$1, 0), 4)), $C12 )/L12} -> 0.77319588 | N13: {=COUNTIFS( rawv3!$F:$F, "Success", INDIRECT("rawv3!" & ADDRESS(1, MATCH($D$2 & " " & N$3, rawv3!$1:$1, 0), 4) & ":" & ADDRESS(1048576, MATCH($D$2 & " " & N$3, rawv3!$1:$1, 0), 4)), N$4, INDIRECT("rawv3!" & ADDRESS(1, MATCH($B$4 & " " & $B10, rawv3!$1:$1, 0), 4) & ":" & ADDRESS(1048576, MATCH($B$4 & " " & $B10, rawv3!$1:$1, 0), 4)), $C12 )/N12} -> 0.79646018 | O13: {=COUNTIFS( rawv3!$F:$F, "Success", INDIRECT("rawv3!" & ADDRESS(1, MATCH($D$2 & " " & N$3, rawv3!$1:$1, 0), 4) & ":" & ADDRESS(1048576, MATCH($D$2 & " " & N$3, rawv3!$1:$1, 0), 4)), O$4, INDIRECT("rawv3!" & ADDRESS(1, MATCH($B$4 & " " & $B10, rawv3!$1:$1, 0), 4) & ":" & ADDRESS(1048576, MATCH($B$4 & " " & $B10, rawv3!$1:$1, 0), 4)), $C12 )/O12} -> 0.75409836 | Q13: {=COUNTIFS( rawv3!$F:$F, "Success", INDIRECT("rawv3!" & ADDRESS(1, MATCH($D$2 & " " & Q$3, rawv3!$1:$1, 0), 4) & ":" & ADDRESS(1048576, MATCH($D$2 & " " & Q$3, rawv3!$1:$1, 0), 4)), Q$4, INDIRECT("rawv3!" & ADDRESS(1, MATCH($B$4 & " " & $B10, rawv3!$1:$1, 0), 4) & ":" & ADDRESS(1048576, MATCH($B$4 & " " & $B10, rawv3!$1:$1, 0), 4)), $C12 )/Q12} -> 0.81818182 | R13: {=COUNTIFS( rawv3!$F:$F, "Success", INDIRECT("rawv3!" & ADDRESS(1, MATCH($D$2 & " " & Q$3, rawv3!$1:$1, 0), 4) & ":" & ADDRESS(1048576, MATCH($D$2 & " " & Q$3, rawv3!$1:$1, 0), 4)), R$4, INDIRECT("rawv3!" & ADDRESS(1, MATCH($B$4 & " " & $B10, rawv3!$1:$1, 0), 4) & ":" & ADDRESS(1048576, MATCH($B$4 & " " & $B10, rawv3!$1:$1, 0), 4)), $C12 )/R12} -> 0.69811321 | T13: {=COUNTIFS( rawv3!$F:$F, "Success", INDIRECT("rawv3!" & ADDRESS(1, MATCH($D$2 & " " & T$3, rawv3!$1:$1, 0), 4) & ":" & ADDRESS(1048576, MATCH($D$2 & " " & T$3, rawv3!$1:$1, 0), 4)), T$4, INDIRECT("rawv3!" & ADDRESS(1, MATCH($B$4 & " " & $B10, rawv3!$1:$1, 0), 4) & ":" & ADDRESS(1048576, MATCH($B$4 & " " & $B10, rawv3!$1:$1, 0), 4)), $C12 )/T12} -> 0.796875 | U13: {=COUNTIFS( rawv3!$F:$F, "Success", INDIRECT("rawv3!" & ADDRESS(1, MATCH($D$2 & " " & T$3, rawv3!$1:$1, 0), 4) & ":" & ADDRESS(1048576, MATCH($D$2 & " " & T$3, rawv3!$1:$1, 0), 4)), U$4, INDIRECT("rawv3!" & ADDRESS(1, MATCH($B$4 & " " & $B10, rawv3!$1:$1, 0), 4) & ":" & ADDRESS(1048576, MATCH($B$4 & " " & $B10, rawv3!$1:$1, 0), 4)), $C12 )/U12} -> 0.73913043 | W13: {=COUNTIFS( rawv3!$F:$F, "Success", INDIRECT("rawv3!" & ADDRESS(1, MATCH($D$2 & " " & W$3, rawv3!$1:$1, 0), 4) & ":" & ADDRESS(1048576, MATCH($D$2 & " " & W$3, rawv3!$1:$1, 0), 4)), W$4, INDIRECT("rawv3!" & ADDRESS(1, MATCH($B$4 & " " & $B10, rawv3!$1:$1, 0), 4) & ":" & ADDRESS(1048576, MATCH($B$4 & " " & $B10, rawv3!$1:$1, 0), 4)), $C12 )/W12} -> 0.76829268 | X13: {=COUNTIFS( rawv3!$F:$F, "Success", INDIRECT("rawv3!" & ADDRESS(1, MATCH($D$2 & " " & W$3, rawv3!$1:$1, 0), 4) & ":" & ADDRESS(1048576, MATCH($D$2 & " " & W$3, rawv3!$1:$1, 0), 4)), X$4, INDIRECT("rawv3!" & ADDRESS(1, MATCH($B$4 & " " & $B10, rawv3!$1:$1, 0), 4) & ":" & ADDRESS(1048576, MATCH($B$4 & " " & $B10, rawv3!$1:$1, 0), 4)), $C12 )/X12} -> 0.79347826 | Z13: {=COUNTIFS( rawv3!$F:$F, "Success", INDIRECT("rawv3!" & ADDRESS(1, MATCH($B$4 & " " & $B10, rawv3!$1:$1, 0), 4) & ":" & ADDRESS(1048576, MATCH($B$4 & " " & $B10, rawv3!$1:$1, 0), 4)), $C12)/Z12} -> 0.7816092 | AA13: {=COUNTIFS( rawv3!$F:$F, "Success", INDIRECT("rawv3!" & ADDRESS(1, MATCH($B$4 & " " & $B10, rawv3!$1:$1, 0), 4) & ":" & ADDRESS(1048576, MATCH($B$4 & " " & $B10, rawv3!$1:$1, 0), 4)), $C12)} -> 136
B15: Drive | C15: Small tangible goals | D15: # | E15: {=COUNTIFS( rawv3!$F:$F, "<>Ongoing", INDIRECT("rawv3!" & ADDRESS(1, MATCH($D$2 & " " & E$3, rawv3!$1:$1, 0), 4) & ":" & ADDRESS(1048576, MATCH($D$2 & " " & E$3, rawv3!$1:$1, 0), 4)), E$4, INDIRECT("rawv3!" & ADDRESS(1, MATCH($B$4 & " " & $B15, rawv3!$1:$1, 0), 4) & ":" & ADDRESS(1048576, MATCH($B$4 & " " & $B15, rawv3!$1:$1, 0), 4)), $C15 )} -> 689 | F15: {=COUNTIFS( rawv3!$F:$F, "<>Ongoing", INDIRECT("rawv3!" & ADDRESS(1, MATCH($D$2 & " " & E$3, rawv3!$1:$1, 0), 4) & ":" & ADDRESS(1048576, MATCH($D$2 & " " & E$3, rawv3!$1:$1, 0), 4)), F$4, INDIRECT("rawv3!" & ADDRESS(1, MATCH($B$4 & " " & $B15, rawv3!$1:$1, 0), 4) & ":" & ADDRESS(1048576, MATCH($B$4 & " " & $B15, rawv3!$1:$1, 0), 4)), $C15 )} -> 708 | H15: {=COUNTIFS( rawv3!$F:$F, "<>Ongoing", INDIRECT("rawv3!" & ADDRESS(1, MATCH($D$2 & " " & H$3, rawv3!$1:$1, 0), 4) & ":" & ADDRESS(1048576, MATCH($D$2 & " " & H$3, rawv3!$1:$1, 0), 4)), H$4, INDIRECT("rawv3!" & ADDRESS(1, MATCH($B$4 & " " & $B15, rawv3!$1:$1, 0), 4) & ":" & ADDRESS(1048576, MATCH($B$4 & " " & $B15, rawv3!$1:$1, 0), 4)), $C15 )} -> 844 | I15: {=COUNTIFS( rawv3!$F:$F, "<>Ongoing", INDIRECT("rawv3!" & ADDRESS(1, MATCH($D$2 & " " & H$3, rawv3!$1:$1, 0), 4) & ":" & ADDRESS(1048576, MATCH($D$2 & " " & H$3, rawv3!$1:$1, 0), 4)), I$4, INDIRECT("rawv3!" & ADDRESS(1, MATCH($B$4 & " " & $B15, rawv3!$1:$1, 0), 4) & ":" & ADDRESS(1048576, MATCH($B$4 & " " & $B15, rawv3!$1:$1, 0), 4)), $C15 )} -> 557 | K15: {=COUNTIFS( rawv3!$F:$F, "<>Ongoing", INDIRECT("rawv3!" & ADDRESS(1, MATCH($D$2 & " " & K$3, rawv3!$1:$1, 0), 4) & ":" & ADDRESS(1048576, MATCH($D$2 & " " & K$3, rawv3!$1:$1, 0), 4)), K$4, INDIRECT("rawv3!" & ADDRESS(1, MATCH($B$4 & " " & $B15, rawv3!$1:$1, 0), 4) & ":" & ADDRESS(1048576, MATCH($B$4 & " " & $B15, rawv3!$1:$1, 0), 4)), $C15 )} -> 790 | L15: {=COUNTIFS( rawv3!$F:$F, "<>Ongoing", INDIRECT("rawv3!" & ADDRESS(1, MATCH($D$2 & " " & K$3, rawv3!$1:$1, 0), 4) & ":" & ADDRESS(1048576, MATCH($D$2 & " " & K$3, rawv3!$1:$1, 0), 4)), L$4, INDIRECT("rawv3!" & ADDRESS(1, MATCH($B$4 & " " & $B15, rawv3!$1:$1, 0), 4) & ":" & ADDRESS(1048576, MATCH($B$4 & " " & $B15, rawv3!$1:$1, 0), 4)), $C15 )} -> 611 | N15: {=COUNTIFS( rawv3!$F:$F, "<>Ongoing", INDIRECT("rawv3!" & ADDRESS(1, MATCH($D$2 & " " & N$3, rawv3!$1:$1, 0), 4) & ":" & ADDRESS(1048576, MATCH($D$2 & " " & N$3, rawv3!$1:$1, 0), 4)), N$4, INDIRECT("rawv3!" & ADDRESS(1, MATCH($B$4 & " " & $B15, rawv3!$1:$1, 0), 4) & ":" & ADDRESS(1048576, MATCH($B$4 & " " & $B15, rawv3!$1:$1, 0), 4)), $C15 )} -> 833 | O15: {=COUNTIFS( rawv3!$F:$F, "<>Ongoing", INDIRECT("rawv3!" & ADDRESS(1, MATCH($D$2 & " " & N$3, rawv3!$1:$1, 0), 4) & ":" & ADDRESS(1048576, MATCH($D$2 & " " & N$3, rawv3!$1:$1, 0), 4)), O$4, INDIRECT("rawv3!" & ADDRESS(1, MATCH($B$4 & " " & $B15, rawv3!$1:$1, 0), 4) & ":" & ADDRESS(1048576, MATCH($B$4 & " " & $B15, rawv3!$1:$1, 0), 4)), $C15 )} -> 568 | Q15: {=COUNTIFS( rawv3!$F:$F, "<>Ongoing", INDIRECT("rawv3!" & ADDRESS(1, MATCH($D$2 & " " & Q$3, rawv3!$1:$1, 0), 4) & ":" & ADDRESS(1048576, MATCH($D$2 & " " & Q$3, rawv3!$1:$1, 0), 4)), Q$4, INDIRECT("rawv3!" & ADDRESS(1, MATCH($B$4 & " " & $B15, rawv3!$1:$1, 0), 4) & ":" & ADDRESS(1048576, MATCH($B$4 & " " & $B15, rawv3!$1:$1, 0), 4)), $C15 )} -> 1006 | R15: {=COUNTIFS( rawv3!$F:$F, "<>Ongoing", INDIRECT("rawv3!" & ADDRESS(1, MATCH($D$2 & " " & Q$3, rawv3!$1:$1, 0), 4) & ":" & ADDRESS(1048576, MATCH($D$2 & " " & Q$3, rawv3!$1:$1, 0), 4)), R$4, INDIRECT("rawv3!" & ADDRESS(1, MATCH($B$4 & " " & $B15, rawv3!$1:$1, 0), 4) & ":" & ADDRESS(1048576, MATCH($B$4 & " " & $B15, rawv3!$1:$1, 0), 4)), $C15 )} -> 394 | T15: {=COUNTIFS( rawv3!$F:$F, "<>Ongoing", INDIRECT("rawv3!" & ADDRESS(1, MATCH($D$2 & " " & T$3, rawv3!$1:$1, 0), 4) & ":" & ADDRESS(1048576, MATCH($D$2 & " " & T$3, rawv3!$1:$1, 0), 4)), T$4, INDIRECT("rawv3!" & ADDRESS(1, MATCH($B$4 & " " & $B15, rawv3!$1:$1, 0), 4) & ":" & ADDRESS(1048576, MATCH($B$4 & " " & $B15, rawv3!$1:$1, 0), 4)), $C15 )} -> 1055 | U15: {=COUNTIFS( rawv3!$F:$F, "<>Ongoing", INDIRECT("rawv3!" & ADDRESS(1, MATCH($D$2 & " " & T$3, rawv3!$1:$1, 0), 4) & ":" & ADDRESS(1048576, MATCH($D$2 & " " & T$3, rawv3!$1:$1, 0), 4)), U$4, INDIRECT("rawv3!" & ADDRESS(1, MATCH($B$4 & " " & $B15, rawv3!$1:$1, 0), 4) & ":" & ADDRESS(1048576, MATCH($B$4 & " " & $B15, rawv3!$1:$1, 0), 4)), $C15 )} -> 345 | W15: {=COUNTIFS( rawv3!$F:$F, "<>Ongoing", INDIRECT("rawv3!" & ADDRESS(1, MATCH($D$2 & " " & W$3, rawv3!$1:$1, 0), 4) & ":" & ADDRESS(1048576, MATCH($D$2 & " " & W$3, rawv3!$1:$1, 0), 4)), W$4, INDIRECT("rawv3!" & ADDRESS(1, MATCH($B$4 & " " & $B15, rawv3!$1:$1, 0), 4) & ":" & ADDRESS(1048576, MATCH($B$4 & " " & $B15, rawv3!$1:$1, 0), 4)), $C15 )} -> 632 | X15: {=COUNTIFS( rawv3!$F:$F, "<>Ongoing", INDIRECT("rawv3!" & ADDRESS(1, MATCH($D$2 & " " & W$3, rawv3!$1:$1, 0), 4) & ":" & ADDRESS(1048576, MATCH($D$2 & " " & W$3, rawv3!$1:$1, 0), 4)), X$4, INDIRECT("rawv3!" & ADDRESS(1, MATCH($B$4 & " " & $B15, rawv3!$1:$1, 0), 4) & ":" & ADDRESS(1048576, MATCH($B$4 & " " & $B15, rawv3!$1:$1, 0), 4)), $C15 )} -> 769 | Z15: {=COUNTIFS( rawv3!$F:$F, "<>Ongoing", INDIRECT("rawv3!" & ADDRESS(1, MATCH($B$4 & " " & $B15, rawv3!$1:$1, 0), 4) & ":" & ADDRESS(1048576, MATCH($B$4 & " " & $B15, rawv3!$1:$1, 0), 4)), $C15)} -> 1401
D16: F90D % | E16: {=COUNTIFS( rawv3!$F:$F, "Success", INDIRECT("rawv3!" & ADDRESS(1, MATCH($D$2 & " " & E$3, rawv3!$1:$1, 0), 4) & ":" & ADDRESS(1048576, MATCH($D$2 & " " & E$3, rawv3!$1:$1, 0), 4)), E$4, INDIRECT("rawv3!" & ADDRESS(1, MATCH($B$4 & " " & $B15, rawv3!$1:$1, 0), 4) & ":" & ADDRESS(1048576, MATCH($B$4 & " " & $B15, rawv3!$1:$1, 0), 4)), $C15 )/E15} -> 0.76632801 | F16: {=COUNTIFS( rawv3!$F:$F, "Success", INDIRECT("rawv3!" & ADDRESS(1, MATCH($D$2 & " " & E$3, rawv3!$1:$1, 0), 4) & ":" & ADDRESS(1048576, MATCH($D$2 & " " & E$3, rawv3!$1:$1, 0), 4)), F$4, INDIRECT("rawv3!" & ADDRESS(1, MATCH($B$4 & " " & $B15, rawv3!$1:$1, 0), 4) & ":" & ADDRESS(1048576, MATCH($B$4 & " " & $B15, rawv3!$1:$1, 0), 4)), $C15 )/F15} -> 0.80932203 | H16: {=COUNTIFS( rawv3!$F:$F, "Success", INDIRECT("rawv3!" & ADDRESS(1, MATCH($D$2 & " " & H$3, rawv3!$1:$1, 0), 4) & ":" & ADDRESS(1048576, MATCH($D$2 & " " & H$3, rawv3!$1:$1, 0), 4)), H$4, INDIRECT("rawv3!" & ADDRESS(1, MATCH($B$4 & " " & $B15, rawv3!$1:$1, 0), 4) & ":" & ADDRESS(1048576, MATCH($B$4 & " " & $B15, rawv3!$1:$1, 0), 4)), $C15 )/H15} -> 0.79265403 | I16: {=COUNTIFS( rawv3!$F:$F, "Success", INDIRECT("rawv3!" & ADDRESS(1, MATCH($D$2 & " " & H$3, rawv3!$1:$1, 0), 4) & ":" & ADDRESS(1048576, MATCH($D$2 & " " & H$3, rawv3!$1:$1, 0), 4)), I$4, INDIRECT("rawv3!" & ADDRESS(1, MATCH($B$4 & " " & $B15, rawv3!$1:$1, 0), 4) & ":" & ADDRESS(1048576, MATCH($B$4 & " " & $B15, rawv3!$1:$1, 0), 4)), $C15 )/I15} -> 0.78276481 | K16: {=COUNTIFS( rawv3!$F:$F, "Success", INDIRECT("rawv3!" & ADDRESS(1, MATCH($D$2 & " " & K$3, rawv3!$1:$1, 0), 4) & ":" & ADDRESS(1048576, MATCH($D$2 & " " & K$3, rawv3!$1:$1, 0), 4)), K$4, INDIRECT("rawv3!" & ADDRESS(1, MATCH($B$4 & " " & $B15, rawv3!$1:$1, 0), 4) & ":" & ADDRESS(1048576, MATCH($B$4 & " " & $B15, rawv3!$1:$1, 0), 4)), $C15 )/K15} -> 0.79746835 | L16: {=COUNTIFS( rawv3!$F:$F, "Success", INDIRECT("rawv3!" & ADDRESS(1, MATCH($D$2 & " " & K$3, rawv3!$1:$1, 0), 4) & ":" & ADDRESS(1048576, MATCH($D$2 & " " & K$3, rawv3!$1:$1, 0), 4)), L$4, INDIRECT("rawv3!" & ADDRESS(1, MATCH($B$4 & " " & $B15, rawv3!$1:$1, 0), 4) & ":" & ADDRESS(1048576, MATCH($B$4 & " " & $B15, rawv3!$1:$1, 0), 4)), $C15 )/L15} -> 0.77741408 | N16: {=COUNTIFS( rawv3!$F:$F, "Success", INDIRECT("rawv3!" & ADDRESS(1, MATCH($D$2 & " " & N$3, rawv3!$1:$1, 0), 4) & ":" & ADDRESS(1048576, MATCH($D$2 & " " & N$3, rawv3!$1:$1, 0), 4)), N$4, INDIRECT("rawv3!" & ADDRESS(1, MATCH($B$4 & " " & $B15, rawv3!$1:$1, 0), 4) & ":" & ADDRESS(1048576, MATCH($B$4 & " " & $B15, rawv3!$1:$1, 0), 4)), $C15 )/N15} -> 0.80552221 | O16: {=COUNTIFS( rawv3!$F:$F, "Success", INDIRECT("rawv3!" & ADDRESS(1, MATCH($D$2 & " " & N$3, rawv3!$1:$1, 0), 4) & ":" & ADDRESS(1048576, MATCH($D$2 & " " & N$3, rawv3!$1:$1, 0), 4)), O$4, INDIRECT("rawv3!" & ADDRESS(1, MATCH($B$4 & " " & $B15, rawv3!$1:$1, 0), 4) & ":" & ADDRESS(1048576, MATCH($B$4 & " " & $B15, rawv3!$1:$1, 0), 4)), $C15 )/O15} -> 0.76408451 | Q16: {=COUNTIFS( rawv3!$F:$F, "Success", INDIRECT("rawv3!" & ADDRESS(1, MATCH($D$2 & " " & Q$3, rawv3!$1:$1, 0), 4) & ":" & ADDRESS(1048576, MATCH($D$2 & " " & Q$3, rawv3!$1:$1, 0), 4)), Q$4, INDIRECT("rawv3!" & ADDRESS(1, MATCH($B$4 & " " & $B15, rawv3!$1:$1, 0), 4) & ":" & ADDRESS(1048576, MATCH($B$4 & " " & $B15, rawv3!$1:$1, 0), 4)), $C15 )/Q15} -> 0.79522863 | R16: {=COUNTIFS( rawv3!$F:$F, "Success", INDIRECT("rawv3!" & ADDRESS(1, MATCH($D$2 & " " & Q$3, rawv3!$1:$1, 0), 4) & ":" & ADDRESS(1048576, MATCH($D$2 & " " & Q$3, rawv3!$1:$1, 0), 4)), R$4, INDIRECT("rawv3!" & ADDRESS(1, MATCH($B$4 & " " & $B15, rawv3!$1:$1, 0), 4) & ":" & ADDRESS(1048576, MATCH($B$4 & " " & $B15, rawv3!$1:$1, 0), 4)), $C15 )/R15} -> 0.7715736 | T16: {=COUNTIFS( rawv3!$F:$F, "Success", INDIRECT("rawv3!" & ADDRESS(1, MATCH($D$2 & " " & T$3, rawv3!$1:$1, 0), 4) & ":" & ADDRESS(1048576, MATCH($D$2 & " " & T$3, rawv3!$1:$1, 0), 4)), T$4, INDIRECT("rawv3!" & ADDRESS(1, MATCH($B$4 & " " & $B15, rawv3!$1:$1, 0), 4) & ":" & ADDRESS(1048576, MATCH($B$4 & " " & $B15, rawv3!$1:$1, 0), 4)), $C15 )/T15} -> 0.79810427 | U16: {=COUNTIFS( rawv3!$F:$F, "Success", INDIRECT("rawv3!" & ADDRESS(1, MATCH($D$2 & " " & T$3, rawv3!$1:$1, 0), 4) & ":" & ADDRESS(1048576, MATCH($D$2 & " " & T$3, rawv3!$1:$1, 0), 4)), U$4, INDIRECT("rawv3!" & ADDRESS(1, MATCH($B$4 & " " & $B15, rawv3!$1:$1, 0), 4) & ":" & ADDRESS(1048576, MATCH($B$4 & " " & $B15, rawv3!$1:$1, 0), 4)), $C15 )/U15} -> 0.75942029 | W16: {=COUNTIFS( rawv3!$F:$F, "Success", INDIRECT("rawv3!" & ADDRESS(1, MATCH($D$2 & " " & W$3, rawv3!$1:$1, 0), 4) & ":" & ADDRESS(1048576, MATCH($D$2 & " " & W$3, rawv3!$1:$1, 0), 4)), W$4, INDIRECT("rawv3!" & ADDRESS(1, MATCH($B$4 & " " & $B15, rawv3!$1:$1, 0), 4) & ":" & ADDRESS(1048576, MATCH($B$4 & " " & $B15, rawv3!$1:$1, 0), 4)), $C15 )/W15} -> 0.78006329 | X16: {=COUNTIFS( rawv3!$F:$F, "Success", INDIRECT("rawv3!" & ADDRESS(1, MATCH($D$2 & " " & W$3, rawv3!$1:$1, 0), 4) & ":" & ADDRESS(1048576, MATCH($D$2 & " " & W$3, rawv3!$1:$1, 0), 4)), X$4, INDIRECT("rawv3!" & ADDRESS(1, MATCH($B$4 & " " & $B15, rawv3!$1:$1, 0), 4) & ":" & ADDRESS(1048576, MATCH($B$4 & " " & $B15, rawv3!$1:$1, 0), 4)), $C15 )/X15} -> 0.79583875 | Z16: {=COUNTIFS( rawv3!$F:$F, "Success", INDIRECT("rawv3!" & ADDRESS(1, MATCH($B$4 & " " & $B15, rawv3!$1:$1, 0), 4) & ":" & ADDRESS(1048576, MATCH($B$4 & " " & $B15, rawv3!$1:$1, 0), 4)), $C15)/Z15} -> 0.78872234 | AA16: {=COUNTIFS( rawv3!$F:$F, "Success", INDIRECT("rawv3!" & ADDRESS(1, MATCH($B$4 & " " & $B15, rawv3!$1:$1, 0), 4) & ":" & ADDRESS(1048576, MATCH($B$4 & " " & $B15, rawv3!$1:$1, 0), 4)), $C15)} -> 1105
C17: Towards visionary ideas | D17: # | E17: {=COUNTIFS( rawv3!$F:$F, "<>Ongoing", INDIRECT("rawv3!" & ADDRESS(1, MATCH($D$2 & " " & E$3, rawv3!$1:$1, 0), 4) & ":" & ADDRESS(1048576, MATCH($D$2 & " " & E$3, rawv3!$1:$1, 0), 4)), E$4, INDIRECT("rawv3!" & ADDRESS(1, MATCH($B$4 & " " & $B15, rawv3!$1:$1, 0), 4) & ":" & ADDRESS(1048576, MATCH($B$4 & " " & $B15, rawv3!$1:$1, 0), 4)), $C17 )} -> 594 | F17: {=COUNTIFS( rawv3!$F:$F, "<>Ongoing", INDIRECT("rawv3!" & ADDRESS(1, MATCH($D$2 & " " & E$3, rawv3!$1:$1, 0), 4) & ":" & ADDRESS(1048576, MATCH($D$2 & " " & E$3, rawv3!$1:$1, 0), 4)), F$4, INDIRECT("rawv3!" & ADDRESS(1, MATCH($B$4 & " " & $B15, rawv3!$1:$1, 0), 4) & ":" & ADDRESS(1048576, MATCH($B$4 & " " & $B15, rawv3!$1:$1, 0), 4)), $C17 )} -> 542 | H17: {=COUNTIFS( rawv3!$F:$F, "<>Ongoing", INDIRECT("rawv3!" & ADDRESS(1, MATCH($D$2 & " " & H$3, rawv3!$1:$1, 0), 4) & ":" & ADDRESS(1048576, MATCH($D$2 & " " & H$3, rawv3!$1:$1, 0), 4)), H$4, INDIRECT("rawv3!" & ADDRESS(1, MATCH($B$4 & " " & $B15, rawv3!$1:$1, 0), 4) & ":" & ADDRESS(1048576, MATCH($B$4 & " " & $B15, rawv3!$1:$1, 0), 4)), $C17 )} -> 700 | I17: {=COUNTIFS( rawv3!$F:$F, "<>Ongoing", INDIRECT("rawv3!" & ADDRESS(1, MATCH($D$2 & " " & H$3, rawv3!$1:$1, 0), 4) & ":" & ADDRESS(1048576, MATCH($D$2 & " " & H$3, rawv3!$1:$1, 0), 4)), I$4, INDIRECT("rawv3!" & ADDRESS(1, MATCH($B$4 & " " & $B15, rawv3!$1:$1, 0), 4) & ":" & ADDRESS(1048576, MATCH($B$4 & " " & $B15, rawv3!$1:$1, 0), 4)), $C17 )} -> 437 | K17: {=COUNTIFS( rawv3!$F:$F, "<>Ongoing", INDIRECT("rawv3!" & ADDRESS(1, MATCH($D$2 & " " & K$3, rawv3!$1:$1, 0), 4) & ":" & ADDRESS(1048576, MATCH($D$2 & " " & K$3, rawv3!$1:$1, 0), 4)), K$4, INDIRECT("rawv3!" & ADDRESS(1, MATCH($B$4 & " " & $B15, rawv3!$1:$1, 0), 4) & ":" & ADDRESS(1048576, MATCH($B$4 & " " & $B15, rawv3!$1:$1, 0), 4)), $C17 )} -> 432 | L17: {=COUNTIFS( rawv3!$F:$F, "<>Ongoing", INDIRECT("rawv3!" & ADDRESS(1, MATCH($D$2 & " " & K$3, rawv3!$1:$1, 0), 4) & ":" & ADDRESS(1048576, MATCH($D$2 & " " & K$3, rawv3!$1:$1, 0), 4)), L$4, INDIRECT("rawv3!" & ADDRESS(1, MATCH($B$4 & " " & $B15, rawv3!$1:$1, 0), 4) & ":" & ADDRESS(1048576, MATCH($B$4 & " " & $B15, rawv3!$1:$1, 0), 4)), $C17 )} -> 704 | N17: {=COUNTIFS( rawv3!$F:$F, "<>Ongoing", INDIRECT("rawv3!" & ADDRESS(1, MATCH($D$2 & " " & N$3, rawv3!$1:$1, 0), 4) & ":" & ADDRESS(1048576, MATCH($D$2 & " " & N$3, rawv3!$1:$1, 0), 4)), N$4, INDIRECT("rawv3!" & ADDRESS(1, MATCH($B$4 & " " & $B15, rawv3!$1:$1, 0), 4) & ":" & ADDRESS(1048576, MATCH($B$4 & " " & $B15, rawv3!$1:$1, 0), 4)), $C17 )} -> 688 | O17: {=COUNTIFS( rawv3!$F:$F, "<>Ongoing", INDIRECT("rawv3!" & ADDRESS(1, MATCH($D$2 & " " & N$3, rawv3!$1:$1, 0), 4) & ":" & ADDRESS(1048576, MATCH($D$2 & " " & N$3, rawv3!$1:$1, 0), 4)), O$4, INDIRECT("rawv3!" & ADDRESS(1, MATCH($B$4 & " " & $B15, rawv3!$1:$1, 0), 4) & ":" & ADDRESS(1048576, MATCH($B$4 & " " & $B15, rawv3!$1:$1, 0), 4)), $C17 )} -> 449 | Q17: {=COUNTIFS( rawv3!$F:$F, "<>Ongoing", INDIRECT("rawv3!" & ADDRESS(1, MATCH($D$2 & " " & Q$3, rawv3!$1:$1, 0), 4) & ":" & ADDRESS(1048576, MATCH($D$2 & " " & Q$3, rawv3!$1:$1, 0), 4)), Q$4, INDIRECT("rawv3!" & ADDRESS(1, MATCH($B$4 & " " & $B15, rawv3!$1:$1, 0), 4) & ":" & ADDRESS(1048576, MATCH($B$4 & " " & $B15, rawv3!$1:$1, 0), 4)), $C17 )} -> 834 | R17: {=COUNTIFS( rawv3!$F:$F, "<>Ongoing", INDIRECT("rawv3!" & ADDRESS(1, MATCH($D$2 & " " & Q$3, rawv3!$1:$1, 0), 4) & ":" & ADDRESS(1048576, MATCH($D$2 & " " & Q$3, rawv3!$1:$1, 0), 4)), R$4, INDIRECT("rawv3!" & ADDRESS(1, MATCH($B$4 & " " & $B15, rawv3!$1:$1, 0), 4) & ":" & ADDRESS(1048576, MATCH($B$4 & " " & $B15, rawv3!$1:$1, 0), 4)), $C17 )} -> 302 | T17: {=COUNTIFS( rawv3!$F:$F, "<>Ongoing", INDIRECT("rawv3!" & ADDRESS(1, MATCH($D$2 & " " & T$3, rawv3!$1:$1, 0), 4) & ":" & ADDRESS(1048576, MATCH($D$2 & " " & T$3, rawv3!$1:$1, 0), 4)), T$4, INDIRECT("rawv3!" & ADDRESS(1, MATCH($B$4 & " " & $B15, rawv3!$1:$1, 0), 4) & ":" & ADDRESS(1048576, MATCH($B$4 & " " & $B15, rawv3!$1:$1, 0), 4)), $C17 )} -> 866 | U17: {=COUNTIFS( rawv3!$F:$F, "<>Ongoing", INDIRECT("rawv3!" & ADDRESS(1, MATCH($D$2 & " " & T$3, rawv3!$1:$1, 0), 4) & ":" & ADDRESS(1048576, MATCH($D$2 & " " & T$3, rawv3!$1:$1, 0), 4)), U$4, INDIRECT("rawv3!" & ADDRESS(1, MATCH($B$4 & " " & $B15, rawv3!$1:$1, 0), 4) & ":" & ADDRESS(1048576, MATCH($B$4 & " " & $B15, rawv3!$1:$1, 0), 4)), $C17 )} -> 271 | W17: {=COUNTIFS( rawv3!$F:$F, "<>Ongoing", INDIRECT("rawv3!" & ADDRESS(1, MATCH($D$2 & " " & W$3, rawv3!$1:$1, 0), 4) & ":" & ADDRESS(1048576, MATCH($D$2 & " " & W$3, rawv3!$1:$1, 0), 4)), W$4, INDIRECT("rawv3!" & ADDRESS(1, MATCH($B$4 & " " & $B15, rawv3!$1:$1, 0), 4) & ":" & ADDRESS(1048576, MATCH($B$4 & " " & $B15, rawv3!$1:$1, 0), 4)), $C17 )} -> 495 | X17: {=COUNTIFS( rawv3!$F:$F, "<>Ongoing", INDIRECT("rawv3!" & ADDRESS(1, MATCH($D$2 & " " & W$3, rawv3!$1:$1, 0), 4) & ":" & ADDRESS(1048576, MATCH($D$2 & " " & W$3, rawv3!$1:$1, 0), 4)), X$4, INDIRECT("rawv3!" & ADDRESS(1, MATCH($B$4 & " " & $B15, rawv3!$1:$1, 0), 4) & ":" & ADDRESS(1048576, MATCH($B$4 & " " & $B15, rawv3!$1:$1, 0), 4)), $C17 )} -> 642 | Z17: {=COUNTIFS( rawv3!$F:$F, "<>Ongoing", INDIRECT("rawv3!" & ADDRESS(1, MATCH($B$4 & " " & $B15, rawv3!$1:$1, 0), 4) & ":" & ADDRESS(1048576, MATCH($B$4 & " " & $B15, rawv3!$1:$1, 0), 4)), $C17)} -> 1137
